Workbook
Name AAA: '[2]28-02-97'!#REF!
Name ACCRUAL: '[3]Acc&Prep'!$A$1:$J$700
Name ACCRUALS: '[3]Acc&Prep'!$D$701
Name Beg_Bal: #REF!
Name CCY: #REF!
Name copy.P_LtoAC: #REF!
Name copyCons_toAA: #REF!
Name Cum_Int: #REF!
Name Data: #REF!
Name data84: '[4]Purchase Order'!$E$52
Name Def.Income: #REF!
Name Direct: [3]TB!$42:$124
Name dtrj: DATE(YEAR([5]Payments!Loan_Start),MONTH([5]Payments!Loan_Start)+Payment_Number,DAY([5]Payments!Loan_Start))
Name dtrj: DATE(YEAR([5]Payments!Loan_Start),MONTH([5]Payments!Loan_Start)+Payment_Number,DAY([5]Payments!Loan_Start))
Name dtrj: DATE(YEAR([6]Payments!Loan_Start),MONTH([6]Payments!Loan_Start)+Payment_Number,DAY([6]Payments!Loan_Start))
Name End_Bal: #REF!
Name Extra_Pay: #REF!
Name Full_Print: #REF!
Name Header_Row: ROW(#REF!)
Name Int: #REF!
Name Interest_Rate: #REF!
Name Last_Row: IF('خزينه السلف '!Values_Entered,Header_Row+'خزينه السلف '!Number_of_Payments,Header_Row)
Name Last_Row: IF('خزينه السلف (2)'!Values_Entered,Header_Row+'خزينه السلف (2)'!Number_of_Payments,Header_Row)
Name Last_Row: IF([7]!Values_Entered,Header_Row+[7]!Number_of_Payments,Header_Row)
Name Loan_Amount: #REF!
Name Loan_Start: #REF!
Name Loan_Years: #REF!
Name MonthEnding: #REF!
Name nnn: Scheduled_Payment+Extra_Payment
Name nnn: Scheduled_Payment+Extra_Payment
Name nnn: Scheduled_Payment+Extra_Payment
Name Num_Pmt_Per_Year: #REF!
Name Number_of_Payments: MATCH(0.01,End_Bal,-1)+1
Name Number_of_Payments: MATCH(0.01,End_Bal,-1)+1
Name Number_of_Payments: MATCH(0.01,End_Bal,-1)+1
Name Pay_Date: #REF!
Name Pay_Num: #REF!
Name Payment_Date: DATE(YEAR(Loan_Start),MONTH(Loan_Start)+Payment_Number,DAY(Loan_Start))
Name Payment_Date: DATE(YEAR(Loan_Start),MONTH(Loan_Start)+Payment_Number,DAY(Loan_Start))
Name Payment_Date: DATE(YEAR(Loan_Start),MONTH(Loan_Start)+Payment_Number,DAY(Loan_Start))
Name Period: #REF!
Name Princ: #REF!
Name print.accruals: '[8]Accruals CPT'!$A$1:$G$469
Name print.B_S: #REF!
Name Print.Bus_Tours: #REF!
Name Print_Area_MI: '[2]28-02-97'!#REF!
Name Print_Area_Reset: OFFSET(Full_Print,0,0,'خزينه السلف '!Last_Row)
Name Print_Area_Reset: OFFSET(Full_Print,0,0,'خزينه السلف (2)'!Last_Row)
Name Print_Area_Reset: OFFSET(Full_Print,0,0,Last_Row)
Name Salaries_Template: #N/A
Name sales: [3]TB!$8:$38
Name Sched_Pay: #REF!
Name Scheduled_Extra_Payments: #REF!
Name Scheduled_Interest_Rate: #REF!
Name Scheduled_Monthly_Payment: #REF!
Name Total_Interest: #REF!
Name Total_Pay: #REF!
Name Total_Payment: Scheduled_Payment+Extra_Payment
Name Total_Payment: Scheduled_Payment+Extra_Payment
Name Total_Payment: Scheduled_Payment+Extra_Payment

Sheet 11-2025
Y1: جزاءات | AA1: غياب | AC1: إجازة بالخصم | AE1: انصراف مبكر | AG1: تأخير | AI1: سلف
A2: الكود | B2: الاسم | C2: الفرع | D2: القطاع | E2: الإدارة | F2: الوظيفة | G2: تاريخ التعيين | H2: تاريخ ترك الخدمة | I2: الرقم القومى | J2: عدد الأشهر | K2: الراتب الشهري | L2: مكافات | M2: بدلات | N2: اجمالي الراتب | O2: المرتب التاميني | P2: حصه الشركه | Q2: حصة العامل في التأمينات | R2: الإعفاء الشخصي | S2: وعاء الفترة | T2: الوعاء السنوي | U2: الضريبة السنوية | V2: الضريبة المستحقة للراتب الشهري | W2: الصافي قبل الخصومات | X2: قيمة اليوم | Y2: عدد | Z2: قيمه جزاءات | AA2: عدد2 | AB2: قيمه غياب | AC2: عدد4 | AD2: قيمه إجازة | AE2: عدد5 | AF2: قيمه إنصراف مبكر | AG2: عدد6 | AH2: قيمه تأخير | AI2: السلف | AJ2: اجمالي الخصومات الشهريه | AK2: صافي الراتب الشهري | AL2: بدلات | AM2: مكافات | AN2: حافز | AO2: اوفر تايم | AP2: تسويات | AQ2: كونتست | AR2: عمولات رايا | AS2: عمولات شركه حالا | AT2: عمولات سفن | AU2: عمولات الاسكندريه | AV2: عمولات كريدي | AW2: عمولات ماني | AX2: عمولات رايه قانوني | AY2: عمولات فاليو قانونى | AZ2: بلتون قانونى | BA2: عمولات تنمية قانونى | BB2: عمولات وسيلة قانونى | BC2: وسيلة 10 | BD2: وسيلة 9 | BE2: تنمية | BF2: عمولات ميد قانوني | BG2: ميد بنك | BH2: ارادة | BI2: عمولة سهولة قانوني | BJ2: اجمالي العمولات | BK2: اجمالي الراتب + العمولات | BL2: المرتب التاميني | BM2: حصه الشركه | BN2: حصة العامل في التأمينات | BO2: الإعفاء الشخصي | BP2: وعاء الفترة | BQ2: الوعاء السنوي | BR2: الضريبة السنوية | BS2: اجمالي الضرائب | BT2: ضريبه العمولات | BU2: المستحق | BW2: إيقاف 50% من الراتب | BX2: المستحق بعد الإيقاف | BY2: القبض
A3: 19 | B3: سحر اوسامة احمد محمد | C3: 20أ القاهرة | D3: التحصيل | E3: شركة حالا | F3: مشرف تحصيل | G3: 45209 | I3: 29611110104501 | J3: 1 | K3: 4982.477 | N3: =SUM('11-2025'!$K3:$M3) -> 4982.477 | O3: 4413.4615 | P3: =O3*18.75% -> 827.52404 | Q3: =O3*11% -> 485.48077 | R3: 1666.6667 | S3: =IF(N3-Q3-R3<0,0,N3-Q3-R3) -> 2830.3296 | T3: =IFERROR(S3/J3,0)*12 -> 33963.955 | U3: =IF(T3<=40000,0, IF(T3<=55000,(T3-40000)*10%, IF(T3<=70000,(T3-55000)*15%+1500, IF(T3<=200000,(T3-70000)*20%+1500+2250, IF(T3<=400000,(T3-200000)*22.5%+1500+2250+26000, IF(T3<=600000,(T3-400000)*25%+1500+2250+26000+45000, IF(AND(T3>600000,T3<=1200000),(T3-400000)*25%+1500+2250+26000+45000 +IFERROR(LOOKUP(T3,{600001;700001;800001;900001},{4000;6750;10250;15250}),0),IF(T3>1200000,((T3-1200000)*27.5%)+300000,0) ))))))) -> 0 | V3: =U3/12*J3 -> 0 | W3: =+'11-2025'!$S3-'11-2025'!$V3+'11-2025'!$R3 -> 4496.9962 | X3: =IFERROR(W3/30,"") -> 149.89987 | Y3: 0 | Z3: =IFERROR(+'11-2025'!$X3*'11-2025'!$Y3,"") -> 0 | AA3: 6 | AB3: =IFERROR(+'11-2025'!$X3*'11-2025'!$AA3,"") -> 899.39925 | AC3: 0 | AD3: =IFERROR(+'11-2025'!$X3*'11-2025'!$AC3,"") -> 0 | AE3: 0 | AF3: =IFERROR(+'11-2025'!$X3*'11-2025'!$AE3,"") -> 0 | AG3: 0 | AH3: =IFERROR(+'11-2025'!$X3*'11-2025'!$AG3,"") -> 0 | AI3: 0 | AJ3: =IFERROR('11-2025'!$Z3+'11-2025'!$AB3+'11-2025'!$AD3+'11-2025'!$AF3+'11-2025'!$AH3+'11-2025'!$AI3,"") -> 899.39925 | AK3: =IFERROR('11-2025'!$W3-'11-2025'!$AJ3,"") -> 3597.597 | AO3: 0 | AR3: 0 | AS3: 713.595 | AT3: 0 | AU3: 0 | AV3: 0 | AW3: 580 | AX3: 0 | AY3: 0 | AZ3: 0 | BA3: 0 | BB3: 0 | BC3: 0 | BD3: 0 | BE3: 0 | BF3: 0 | BG3: 1616.7525 | BH3: 0 | BI3: 0 | BJ3: =BD3+BC3+BB3+BA3+AZ3+AY3+AX3+AW3+AV3+AU3+AT3+AS3+AR3+BE3+BF3+BG3+BH3+BI3 -> 2910.3475 | BK3: =BJ3+AM3+AL3+'11-2025'!$N3+AN3+AO3 -> 7892.8245 | BL3: ='11-2025'!$O3 -> 4413.4615 | BM3: =BL3*18.75% -> 827.52404 | BN3: =BL3*11% -> 485.48077 | BO3: =+R3 -> 1666.6667 | BP3: =IF(BK3-BN3-BO3<0,0,BK3-BN3-BO3) -> 5740.6771 | BQ3: =IFERROR(BP3/'11-2025'!$J3,0)*12 -> 68888.125 | BR3: =IF(BQ3<=40000,0, IF(BQ3<=55000,(BQ3-40000)*10%, IF(BQ3<=70000,(BQ3-55000)*15%+1500, IF(BQ3<=200000,(BQ3-70000)*20%+1500+2250, IF(BQ3<=400000,(BQ3-200000)*22.5%+1500+2250+26000, IF(BQ3<=600000,(BQ3-400000)*25%+1500+2250+26000+45000, IF(AND(BQ3>600000,BQ3<=1200000),(BQ3-400000)*25%+1500+2250+26000+45000 +IFERROR(LOOKUP(BQ3,{600001;700001;800001;900001},{4000;6750;10250;15250}),0),IF(BQ3>1200000,((BQ3-1200000)*27.5%)+300000,0) ))))))) -> 3583.2187 | BS3: =(BR3/12*'11-2025'!$J3) -> 298.60156 | BT3: =BS3-'11-2025'!$V3 -> 298.60156 | BU3: =IFERROR(+'11-2025'!$W3+AL3+AM3+BJ3-'11-2025'!$AJ3-BT3+AN3+AO3,"")-AL3+AP3+AQ3 -> 6209.3429 | BX3: =+BU3-BW3 -> 6209.3429 | BY3: فيزا
A4: 20 | B4: عبد العزيز صلاح عبد العزيز على حسن | C4: 20أ القاهرة | D4: الادارى | E4: الشئون القانونية | F4: مشرف قضائى | G4: 45003 | I4: 29703150100399 | J4: 1 | K4: 4657.39 | N4: =SUM('11-2025'!$K4:$M4) -> 4657.39 | O4: 3730.8462 | P4: =O4*18.75% -> 699.53365 | Q4: =O4*11% -> 410.39308 | R4: 1666.6667 | S4: =IF(N4-Q4-R4<0,0,N4-Q4-R4) -> 2580.3303 | T4: =IFERROR(S4/J4,0)*12 -> 30963.963 | U4: =IF(T4<=40000,0, IF(T4<=55000,(T4-40000)*10%, IF(T4<=70000,(T4-55000)*15%+1500, IF(T4<=200000,(T4-70000)*20%+1500+2250, IF(T4<=400000,(T4-200000)*22.5%+1500+2250+26000, IF(T4<=600000,(T4-400000)*25%+1500+2250+26000+45000, IF(AND(T4>600000,T4<=1200000),(T4-400000)*25%+1500+2250+26000+45000 +IFERROR(LOOKUP(T4,{600001;700001;800001;900001},{4000;6750;10250;15250}),0),IF(T4>1200000,((T4-1200000)*27.5%)+300000,0) ))))))) -> 0 | V4: =U4/12*J4 -> 0 | W4: =+'11-2025'!$S4-'11-2025'!$V4+'11-2025'!$R4 -> 4246.9969 | X4: =IFERROR(W4/30,"") -> 141.56656 | Y4: 0 | Z4: =IFERROR(+'11-2025'!$X4*'11-2025'!$Y4,"") -> 0 | AA4: 0 | AB4: =IFERROR(+'11-2025'!$X4*'11-2025'!$AA4,"") -> 0 | AC4: 0 | AD4: =IFERROR(+'11-2025'!$X4*'11-2025'!$AC4,"") -> 0 | AE4: 0 | AF4: =IFERROR(+'11-2025'!$X4*'11-2025'!$AE4,"") -> 0 | AG4: 0 | AH4: =IFERROR(+'11-2025'!$X4*'11-2025'!$AG4,"") -> 0 | AI4: 0 | AJ4: =IFERROR('11-2025'!$Z4+'11-2025'!$AB4+'11-2025'!$AD4+'11-2025'!$AF4+'11-2025'!$AH4+'11-2025'!$AI4,"") -> 0 | AK4: =IFERROR('11-2025'!$W4-'11-2025'!$AJ4,"") -> 4246.9969 | AM4: 2000 | AO4: 0 | AR4: 0 | AS4: 0 | AT4: 0 | AU4: 0 | AV4: 0 | AW4: 0 | AX4: 1350 | AY4: 45 | AZ4: 0 | BA4: 0 | BB4: 35 | BC4: 0 | BD4: 0 | BE4: 0 | BF4: 40 | BG4: 0 | BH4: 0 | BI4: 175 | BJ4: =BD4+BC4+BB4+BA4+AZ4+AY4+AX4+AW4+AV4+AU4+AT4+AS4+AR4+BE4+BF4+BG4+BH4+BI4 -> 1645 | BK4: =BJ4+AM4+AL4+'11-2025'!$N4+AN4+AO4 -> 8302.39 | BL4: ='11-2025'!$O4 -> 3730.8462 | BM4: =BL4*18.75% -> 699.53365 | BN4: =BL4*11% -> 410.39308 | BO4: =+R4 -> 1666.6667 | BP4: =IF(BK4-BN4-BO4<0,0,BK4-BN4-BO4) -> 6225.3303 | BQ4: =IFERROR(BP4/'11-2025'!$J4,0)*12 -> 74703.963 | BR4: =IF(BQ4<=40000,0, IF(BQ4<=55000,(BQ4-40000)*10%, IF(BQ4<=70000,(BQ4-55000)*15%+1500, IF(BQ4<=200000,(BQ4-70000)*20%+1500+2250, IF(BQ4<=400000,(BQ4-200000)*22.5%+1500+2250+26000, IF(BQ4<=600000,(BQ4-400000)*25%+1500+2250+26000+45000, IF(AND(BQ4>600000,BQ4<=1200000),(BQ4-400000)*25%+1500+2250+26000+45000 +IFERROR(LOOKUP(BQ4,{600001;700001;800001;900001},{4000;6750;10250;15250}),0),IF(BQ4>1200000,((BQ4-1200000)*27.5%)+300000,0) ))))))) -> 4690.7926 | BS4: =(BR4/12*'11-2025'!$J4) -> 390.89938 | BT4: =BS4-'11-2025'!$V4 -> 390.89938 | BU4: =IFERROR(+'11-2025'!$W4+AL4+AM4+BJ4-'11-2025'!$AJ4-BT4+AN4+AO4,"")-AL4+AP4+AQ4 -> 7501.0975 | BV4: مكافاة عن طبيعة عمل البحث عن مقر للشركة مستخدما الاسكوتر الخاص | BX4: =+BU4-BW4 -> 7501.0975 | BY4: فيزا
A5: 31 | B5: محمود النادى أبو الحسن احمد | C5: 25ج القاهرة | D5: التحصيل | E5: متعدد | F5: كبير مشرفى تحصيل | G5: 45020 | I5: 28504108800236 | J5: 1 | K5: 8774.76 | N5: =SUM('11-2025'!$K5:$M5) -> 8774.76 | O5: 5230.7718 | P5: =O5*18.75% -> 980.76972 | Q5: =O5*11% -> 575.3849 | R5: 1666.6667 | S5: =IF(N5-Q5-R5<0,0,N5-Q5-R5) -> 6532.7084 | T5: =IFERROR(S5/J5,0)*12 -> 78392.501 | U5: =IF(T5<=40000,0, IF(T5<=55000,(T5-40000)*10%, IF(T5<=70000,(T5-55000)*15%+1500, IF(T5<=200000,(T5-70000)*20%+1500+2250, IF(T5<=400000,(T5-200000)*22.5%+1500+2250+26000, IF(T5<=600000,(T5-400000)*25%+1500+2250+26000+45000, IF(AND(T5>600000,T5<=1200000),(T5-400000)*25%+1500+2250+26000+45000 +IFERROR(LOOKUP(T5,{600001;700001;800001;900001},{4000;6750;10250;15250}),0),IF(T5>1200000,((T5-1200000)*27.5%)+300000,0) ))))))) -> 5428.5002 | V5: =U5/12*J5 -> 452.37502 | W5: =+'11-2025'!$S5-'11-2025'!$V5+'11-2025'!$R5 -> 7747.0001 | X5: =IFERROR(W5/30,"") -> 258.23334 | Y5: 0 | Z5: =IFERROR(+'11-2025'!$X5*'11-2025'!$Y5,"") -> 0 | AA5: 0 | AB5: =IFERROR(+'11-2025'!$X5*'11-2025'!$AA5,"") -> 0 | AC5: 0 | AD5: =IFERROR(+'11-2025'!$X5*'11-2025'!$AC5,"") -> 0 | AE5: 0 | AF5: =IFERROR(+'11-2025'!$X5*'11-2025'!$AE5,"") -> 0 | AG5: 0 | AH5: =IFERROR(+'11-2025'!$X5*'11-2025'!$AG5,"") -> 0 | AI5: 3000 | AJ5: =IFERROR('11-2025'!$Z5+'11-2025'!$AB5+'11-2025'!$AD5+'11-2025'!$AF5+'11-2025'!$AH5+'11-2025'!$AI5,"") -> 3000 | AK5: =IFERROR('11-2025'!$W5-'11-2025'!$AJ5,"") -> 4747.0001 | AM5: =2500+500 -> 3000 | AO5: 140 | AR5: 0 | AS5: 0 | AT5: 0 | AU5: 0 | AV5: 9975.4419 | AW5: 0 | AX5: 0 | AY5: 0 | AZ5: 0 | BA5: 0 | BB5: 0 | BC5: 1394.2475 | BD5: 2236.73 | BE5: 0 | BF5: 0 | BG5: 0 | BH5: 0 | BI5: 0 | BJ5: =BD5+BC5+BB5+BA5+AZ5+AY5+AX5+AW5+AV5+AU5+AT5+AS5+AR5+BE5+BF5+BG5+BH5+BI5 -> 13606.419 | BK5: =BJ5+AM5+AL5+'11-2025'!$N5+AN5+AO5 -> 25521.179 | BL5: ='11-2025'!$O5 -> 5230.7718 | BM5: =BL5*18.75% -> 980.76972 | BN5: =BL5*11% -> 575.3849 | BO5: =+R5 -> 1666.6667 | BP5: =IF(BK5-BN5-BO5<0,0,BK5-BN5-BO5) -> 23279.128 | BQ5: =IFERROR(BP5/'11-2025'!$J5,0)*12 -> 279349.53 | BR5: =IF(BQ5<=40000,0, IF(BQ5<=55000,(BQ5-40000)*10%, IF(BQ5<=70000,(BQ5-55000)*15%+1500, IF(BQ5<=200000,(BQ5-70000)*20%+1500+2250, IF(BQ5<=400000,(BQ5-200000)*22.5%+1500+2250+26000, IF(BQ5<=600000,(BQ5-400000)*25%+1500+2250+26000+45000, IF(AND(BQ5>600000,BQ5<=1200000),(BQ5-400000)*25%+1500+2250+26000+45000 +IFERROR(LOOKUP(BQ5,{600001;700001;800001;900001},{4000;6750;10250;15250}),0),IF(BQ5>1200000,((BQ5-1200000)*27.5%)+300000,0) ))))))) -> 47603.645 | BS5: =(BR5/12*'11-2025'!$J5) -> 3966.9704 | BT5: =BS5-'11-2025'!$V5 -> 3514.5954 | BU5: =IFERROR(+'11-2025'!$W5+AL5+AM5+BJ5-'11-2025'!$AJ5-BT5+AN5+AO5,"")-AL5+AP5+AQ5 -> 17978.824 | BV5: مكافاة تشجيعية Cae Loans + C.C تعليمات ا/وليد | BX5: =+BU5-BW5 -> 17978.824 | BY5: فيزا
A6: 35 | B6: رحمة مصطفى خلف الله حسانين | C6: 25ج القاهرة | D6: الادارى | E6: منسقى البيانات | F6: رئيس فريق عمل | G6: 45285 | I6: 30111210101161 | J6: 1 | K6: 4657.39 | N6: =SUM('11-2025'!$K6:$M6) -> 4657.39 | O6: 3730.8462 | P6: =O6*18.75% -> 699.53365 | Q6: =O6*11% -> 410.39308 | R6: 1666.6667 | S6: =IF(N6-Q6-R6<0,0,N6-Q6-R6) -> 2580.3303 | T6: =IFERROR(S6/J6,0)*12 -> 30963.963 | U6: =IF(T6<=40000,0, IF(T6<=55000,(T6-40000)*10%, IF(T6<=70000,(T6-55000)*15%+1500, IF(T6<=200000,(T6-70000)*20%+1500+2250, IF(T6<=400000,(T6-200000)*22.5%+1500+2250+26000, IF(T6<=600000,(T6-400000)*25%+1500+2250+26000+45000, IF(AND(T6>600000,T6<=1200000),(T6-400000)*25%+1500+2250+26000+45000 +IFERROR(LOOKUP(T6,{600001;700001;800001;900001},{4000;6750;10250;15250}),0),IF(T6>1200000,((T6-1200000)*27.5%)+300000,0) ))))))) -> 0 | V6: =U6/12*J6 -> 0 | W6: =+'11-2025'!$S6-'11-2025'!$V6+'11-2025'!$R6 -> 4246.9969 | X6: =IFERROR(W6/30,"") -> 141.56656 | Y6: 0 | Z6: =IFERROR(+'11-2025'!$X6*'11-2025'!$Y6,"") -> 0 | AA6: 0 | AB6: =IFERROR(+'11-2025'!$X6*'11-2025'!$AA6,"") -> 0 | AC6: 2 | AD6: =IFERROR(+'11-2025'!$X6*'11-2025'!$AC6,"") -> 283.13313 | AE6: 0 | AF6: =IFERROR(+'11-2025'!$X6*'11-2025'!$AE6,"") -> 0 | AG6: 0 | AH6: =IFERROR(+'11-2025'!$X6*'11-2025'!$AG6,"") -> 0 | AI6: 0 | AJ6: =IFERROR('11-2025'!$Z6+'11-2025'!$AB6+'11-2025'!$AD6+'11-2025'!$AF6+'11-2025'!$AH6+'11-2025'!$AI6,"") -> 283.13313 | AK6: =IFERROR('11-2025'!$W6-'11-2025'!$AJ6,"") -> 3963.8638 | AO6: 0 | AR6: 0 | AS6: 0 | AT6: 0 | AU6: 0 | AV6: 0 | AW6: 0 | AX6: 0 | AY6: 0 | AZ6: 0 | BA6: 0 | BB6: 0 | BC6: 0 | BD6: 0 | BE6: 0 | BF6: 0 | BG6: 0 | BH6: 0 | BI6: 0 | BJ6: =BD6+BC6+BB6+BA6+AZ6+AY6+AX6+AW6+AV6+AU6+AT6+AS6+AR6+BE6+BF6+BG6+BH6+BI6 -> 0 | BK6: =BJ6+AM6+AL6+'11-2025'!$N6+AN6+AO6 -> 4657.39 | BL6: ='11-2025'!$O6 -> 3730.8462 | BM6: =BL6*18.75% -> 699.53365 | BN6: =BL6*11% -> 410.39308 | BO6: =+R6 -> 1666.6667 | BP6: =IF(BK6-BN6-BO6<0,0,BK6-BN6-BO6) -> 2580.3303 | BQ6: =IFERROR(BP6/'11-2025'!$J6,0)*12 -> 30963.963 | BR6: =IF(BQ6<=40000,0, IF(BQ6<=55000,(BQ6-40000)*10%, IF(BQ6<=70000,(BQ6-55000)*15%+1500, IF(BQ6<=200000,(BQ6-70000)*20%+1500+2250, IF(BQ6<=400000,(BQ6-200000)*22.5%+1500+2250+26000, IF(BQ6<=600000,(BQ6-400000)*25%+1500+2250+26000+45000, IF(AND(BQ6>600000,BQ6<=1200000),(BQ6-400000)*25%+1500+2250+26000+45000 +IFERROR(LOOKUP(BQ6,{600001;700001;800001;900001},{4000;6750;10250;15250}),0),IF(BQ6>1200000,((BQ6-1200000)*27.5%)+300000,0) ))))))) -> 0 | BS6: =(BR6/12*'11-2025'!$J6) -> 0 | BT6: =BS6-'11-2025'!$V6 -> 0 | BU6: =IFERROR(+'11-2025'!$W6+AL6+AM6+BJ6-'11-2025'!$AJ6-BT6+AN6+AO6,"")-AL6+AP6+AQ6 -> 3963.8638 | BX6: =+BU6-BW6 -> 3963.8638 | BY6: فيزا
A7: 45 | B7: محمد مجدى ربيع عبد الغنى جاد | C7: 20أ القاهرة | D7: التحصيل | E7: بنك الإسكندرية | F7: محاسب | G7: 45400 | I7: 28409261402239 | J7: 1 | K7: 5322.38 | N7: =SUM('11-2025'!$K7:$M7) -> 5322.38 | O7: 5230.7692 | P7: =O7*18.75% -> 980.76923 | Q7: =O7*11% -> 575.38462 | R7: 1666.6667 | S7: =IF(N7-Q7-R7<0,0,N7-Q7-R7) -> 3080.3287 | T7: =IFERROR(S7/J7,0)*12 -> 36963.945 | U7: =IF(T7<=40000,0, IF(T7<=55000,(T7-40000)*10%, IF(T7<=70000,(T7-55000)*15%+1500, IF(T7<=200000,(T7-70000)*20%+1500+2250, IF(T7<=400000,(T7-200000)*22.5%+1500+2250+26000, IF(T7<=600000,(T7-400000)*25%+1500+2250+26000+45000, IF(AND(T7>600000,T7<=1200000),(T7-400000)*25%+1500+2250+26000+45000 +IFERROR(LOOKUP(T7,{600001;700001;800001;900001},{4000;6750;10250;15250}),0),IF(T7>1200000,((T7-1200000)*27.5%)+300000,0) ))))))) -> 0 | V7: =U7/12*J7 -> 0 | W7: =+'11-2025'!$S7-'11-2025'!$V7+'11-2025'!$R7 -> 4746.9954 | X7: =IFERROR(W7/30,"") -> 158.23318 | Y7: 0 | Z7: =IFERROR(+'11-2025'!$X7*'11-2025'!$Y7,"") -> 0 | AA7: 0 | AB7: =IFERROR(+'11-2025'!$X7*'11-2025'!$AA7,"") -> 0 | AC7: 0 | AD7: =IFERROR(+'11-2025'!$X7*'11-2025'!$AC7,"") -> 0 | AE7: 0 | AF7: =IFERROR(+'11-2025'!$X7*'11-2025'!$AE7,"") -> 0 | AG7: 0 | AH7: =IFERROR(+'11-2025'!$X7*'11-2025'!$AG7,"") -> 0 | AI7: 1500 | AJ7: =IFERROR('11-2025'!$Z7+'11-2025'!$AB7+'11-2025'!$AD7+'11-2025'!$AF7+'11-2025'!$AH7+'11-2025'!$AI7,"") -> 1500 | AK7: =IFERROR('11-2025'!$W7-'11-2025'!$AJ7,"") -> 3246.9954 | AO7: 20 | AP7: -83 | AR7: 0 | AS7: 0 | AT7: 0 | AU7: 316.67138 | AV7: 0 | AW7: 0 | AX7: 0 | AY7: 0 | AZ7: 0 | BA7: 0 | BB7: 0 | BC7: 0 | BD7: 0 | BE7: 0 | BF7: 0 | BG7: 0 | BH7: 0 | BI7: 0 | BJ7: =BD7+BC7+BB7+BA7+AZ7+AY7+AX7+AW7+AV7+AU7+AT7+AS7+AR7+BE7+BF7+BG7+BH7+BI7 -> 316.67138 | BK7: =BJ7+AM7+AL7+'11-2025'!$N7+AN7+AO7 -> 5659.0514 | BL7: ='11-2025'!$O7 -> 5230.7692 | BM7: =BL7*18.75% -> 980.76923 | BN7: =BL7*11% -> 575.38462 | BO7: =+R7 -> 1666.6667 | BP7: =IF(BK7-BN7-BO7<0,0,BK7-BN7-BO7) -> 3417.0001 | BQ7: =IFERROR(BP7/'11-2025'!$J7,0)*12 -> 41004.001 | BR7: =IF(BQ7<=40000,0, IF(BQ7<=55000,(BQ7-40000)*10%, IF(BQ7<=70000,(BQ7-55000)*15%+1500, IF(BQ7<=200000,(BQ7-70000)*20%+1500+2250, IF(BQ7<=400000,(BQ7-200000)*22.5%+1500+2250+26000, IF(BQ7<=600000,(BQ7-400000)*25%+1500+2250+26000+45000, IF(AND(BQ7>600000,BQ7<=1200000),(BQ7-400000)*25%+1500+2250+26000+45000 +IFERROR(LOOKUP(BQ7,{600001;700001;800001;900001},{4000;6750;10250;15250}),0),IF(BQ7>1200000,((BQ7-1200000)*27.5%)+300000,0) ))))))) -> 100.40011 | BS7: =(BR7/12*'11-2025'!$J7) -> 8.366676 | BT7: =BS7-'11-2025'!$V7 -> 8.366676 | BU7: =IFERROR(+'11-2025'!$W7+AL7+AM7+BJ7-'11-2025'!$AJ7-BT7+AN7+AO7,"")-AL7+AP7+AQ7 -> 3492.3001 | BV7: خصم قيمة باقة التليفون | BX7: =+BU7-BW7 -> 3492.3001 | BY7: فيزا
A8: 54 | B8: رحاب عبد الهادى احمد بدوى | C8: 25ج القاهرة | D8: التحصيل | E8: شركة وسيلة | F8: نائب كبير مشرفى تحصيل | G8: 45053 | I8: 28706021401264 | J8: 1 | K8: 4753 | N8: =SUM('11-2025'!$K8:$M8) -> 4753 | O8: 5069.2692 | P8: =O8*18.75% -> 950.48798 | Q8: =O8*11% -> 557.61962 | R8: 1666.6667 | S8: =IF(N8-Q8-R8<0,0,N8-Q8-R8) -> 2528.7137 | T8: =IFERROR(S8/J8,0)*12 -> 30344.565 | U8: =IF(T8<=40000,0, IF(T8<=55000,(T8-40000)*10%, IF(T8<=70000,(T8-55000)*15%+1500, IF(T8<=200000,(T8-70000)*20%+1500+2250, IF(T8<=400000,(T8-200000)*22.5%+1500+2250+26000, IF(T8<=600000,(T8-400000)*25%+1500+2250+26000+45000, IF(AND(T8>600000,T8<=1200000),(T8-400000)*25%+1500+2250+26000+45000 +IFERROR(LOOKUP(T8,{600001;700001;800001;900001},{4000;6750;10250;15250}),0),IF(T8>1200000,((T8-1200000)*27.5%)+300000,0) ))))))) -> 0 | V8: =U8/12*J8 -> 0 | W8: =+'11-2025'!$S8-'11-2025'!$V8+'11-2025'!$R8 -> 4195.3804 | X8: =IFERROR(W8/30,"") -> 139.84601 | Y8: 0 | Z8: =IFERROR(+'11-2025'!$X8*'11-2025'!$Y8,"") -> 0 | AA8: 0 | AB8: =IFERROR(+'11-2025'!$X8*'11-2025'!$AA8,"") -> 0 | AC8: 0 | AD8: =IFERROR(+'11-2025'!$X8*'11-2025'!$AC8,"") -> 0 | AE8: 0 | AF8: =IFERROR(+'11-2025'!$X8*'11-2025'!$AE8,"") -> 0 | AG8: 0 | AH8: =IFERROR(+'11-2025'!$X8*'11-2025'!$AG8,"") -> 0 | AI8: 500 | AJ8: =IFERROR('11-2025'!$Z8+'11-2025'!$AB8+'11-2025'!$AD8+'11-2025'!$AF8+'11-2025'!$AH8+'11-2025'!$AI8,"") -> 500 | AK8: =IFERROR('11-2025'!$W8-'11-2025'!$AJ8,"") -> 3695.3804 | AM8: 300 | AO8: 60 | AR8: 0 | AS8: 0 | AT8: 0 | AU8: 0 | AV8: 427.62 | AW8: 0 | AX8: 0 | AY8: 0 | AZ8: 0 | BA8: 0 | BB8: 0 | BC8: 2872.285 | BD8: 5673.46 | BE8: 0 | BF8: 0 | BG8: 0 | BH8: 0 | BI8: 0 | BJ8: =BD8+BC8+BB8+BA8+AZ8+AY8+AX8+AW8+AV8+AU8+AT8+AS8+AR8+BE8+BF8+BG8+BH8+BI8 -> 8973.365 | BK8: =BJ8+AM8+AL8+'11-2025'!$N8+AN8+AO8 -> 14086.365 | BL8: ='11-2025'!$O8 -> 5069.2692 | BM8: =BL8*18.75% -> 950.48798 | BN8: =BL8*11% -> 557.61962 | BO8: =+R8 -> 1666.6667 | BP8: =IF(BK8-BN8-BO8<0,0,BK8-BN8-BO8) -> 11862.079 | BQ8: =IFERROR(BP8/'11-2025'!$J8,0)*12 -> 142344.94 | BR8: =IF(BQ8<=40000,0, IF(BQ8<=55000,(BQ8-40000)*10%, IF(BQ8<=70000,(BQ8-55000)*15%+1500, IF(BQ8<=200000,(BQ8-70000)*20%+1500+2250, IF(BQ8<=400000,(BQ8-200000)*22.5%+1500+2250+26000, IF(BQ8<=600000,(BQ8-400000)*25%+1500+2250+26000+45000, IF(AND(BQ8>600000,BQ8<=1200000),(BQ8-400000)*25%+1500+2250+26000+45000 +IFERROR(LOOKUP(BQ8,{600001;700001;800001;900001},{4000;6750;10250;15250}),0),IF(BQ8>1200000,((BQ8-1200000)*27.5%)+300000,0) ))))))) -> 18218.989 | BS8: =(BR8/12*'11-2025'!$J8) -> 1518.2491 | BT8: =BS8-'11-2025'!$V8 -> 1518.2491 | BU8: =IFERROR(+'11-2025'!$W8+AL8+AM8+BJ8-'11-2025'!$AJ8-BT8+AN8+AO8,"")-AL8+AP8+AQ8 -> 11510.496 | BV8: مكافاة ترشيح | BX8: =+BU8-BW8 -> 11510.496 | BY8: فيزا
A9: 60 | B9: مروة مصطفى على جاد | C9: 25ج القاهرة | D9: التحصيل | E9: مصرف أبو ظبى الاسلامى | F9: مشرف تحصيل | G9: 45062 | I9: 29912120104665 | J9: 1 | K9: 4250.46 | N9: =SUM('11-2025'!$K9:$M9) -> 4250.46 | O9: 4576.9231 | P9: =O9*18.75% -> 858.17308 | Q9: =O9*11% -> 503.46154 | R9: 1666.6667 | S9: =IF(N9-Q9-R9<0,0,N9-Q9-R9) -> 2080.3318 | T9: =IFERROR(S9/J9,0)*12 -> 24963.982 | U9: =IF(T9<=40000,0, IF(T9<=55000,(T9-40000)*10%, IF(T9<=70000,(T9-55000)*15%+1500, IF(T9<=200000,(T9-70000)*20%+1500+2250, IF(T9<=400000,(T9-200000)*22.5%+1500+2250+26000, IF(T9<=600000,(T9-400000)*25%+1500+2250+26000+45000, IF(AND(T9>600000,T9<=1200000),(T9-400000)*25%+1500+2250+26000+45000 +IFERROR(LOOKUP(T9,{600001;700001;800001;900001},{4000;6750;10250;15250}),0),IF(T9>1200000,((T9-1200000)*27.5%)+300000,0) ))))))) -> 0 | V9: =U9/12*J9 -> 0 | W9: =+'11-2025'!$S9-'11-2025'!$V9+'11-2025'!$R9 -> 3746.9985 | X9: =IFERROR(W9/30,"") -> 124.89995 | Y9: 0 | Z9: =IFERROR(+'11-2025'!$X9*'11-2025'!$Y9,"") -> 0 | AA9: 0 | AB9: =IFERROR(+'11-2025'!$X9*'11-2025'!$AA9,"") -> 0 | AC9: 0 | AD9: =IFERROR(+'11-2025'!$X9*'11-2025'!$AC9,"") -> 0 | AE9: 0 | AF9: =IFERROR(+'11-2025'!$X9*'11-2025'!$AE9,"") -> 0 | AG9: 0 | AH9: =IFERROR(+'11-2025'!$X9*'11-2025'!$AG9,"") -> 0 | AI9: 0 | AJ9: =IFERROR('11-2025'!$Z9+'11-2025'!$AB9+'11-2025'!$AD9+'11-2025'!$AF9+'11-2025'!$AH9+'11-2025'!$AI9,"") -> 0 | AK9: =IFERROR('11-2025'!$W9-'11-2025'!$AJ9,"") -> 3746.9985 | AO9: 600 | AR9: 3923.1577 | AS9: 0 | AT9: 0 | AU9: 0 | AV9: 0 | AW9: 0 | AX9: 0 | AY9: 0 | AZ9: 0 | BA9: 0 | BB9: 0 | BC9: 0 | BD9: 0 | BE9: 0 | BF9: 0 | BG9: 0 | BH9: 0 | BI9: 0 | BJ9: =BD9+BC9+BB9+BA9+AZ9+AY9+AX9+AW9+AV9+AU9+AT9+AS9+AR9+BE9+BF9+BG9+BH9+BI9 -> 3923.1577 | BK9: =BJ9+AM9+AL9+'11-2025'!$N9+AN9+AO9 -> 8773.6177 | BL9: ='11-2025'!$O9 -> 4576.9231 | BM9: =BL9*18.75% -> 858.17308 | BN9: =BL9*11% -> 503.46154 | BO9: =+R9 -> 1666.6667 | BP9: =IF(BK9-BN9-BO9<0,0,BK9-BN9-BO9) -> 6603.4895 | BQ9: =IFERROR(BP9/'11-2025'!$J9,0)*12 -> 79241.874 | BR9: =IF(BQ9<=40000,0, IF(BQ9<=55000,(BQ9-40000)*10%, IF(BQ9<=70000,(BQ9-55000)*15%+1500, IF(BQ9<=200000,(BQ9-70000)*20%+1500+2250, IF(BQ9<=400000,(BQ9-200000)*22.5%+1500+2250+26000, IF(BQ9<=600000,(BQ9-400000)*25%+1500+2250+26000+45000, IF(AND(BQ9>600000,BQ9<=1200000),(BQ9-400000)*25%+1500+2250+26000+45000 +IFERROR(LOOKUP(BQ9,{600001;700001;800001;900001},{4000;6750;10250;15250}),0),IF(BQ9>1200000,((BQ9-1200000)*27.5%)+300000,0) ))))))) -> 5598.3748 | BS9: =(BR9/12*'11-2025'!$J9) -> 466.53124 | BT9: =BS9-'11-2025'!$V9 -> 466.53124 | BU9: =IFERROR(+'11-2025'!$W9+AL9+AM9+BJ9-'11-2025'!$AJ9-BT9+AN9+AO9,"")-AL9+AP9+AQ9 -> 7803.6249 | BX9: =+BU9-BW9 -> 7803.6249
A10: 62 | B10: محمد مجدى السيد عبد الدايم | C10: 20أ القاهرة | D10: الادارى | E10: الشئون القانونية | F10: مشرف قضائى | G10: 45066 | I10: 29710280100451 | J10: 1 | K10: 4657.39 | N10: =SUM('11-2025'!$K10:$M10) -> 4657.39 | O10: 3730.8462 | P10: =O10*18.75% -> 699.53365 | Q10: =O10*11% -> 410.39308 | R10: 1666.6667 | S10: =IF(N10-Q10-R10<0,0,N10-Q10-R10) -> 2580.3303 | T10: =IFERROR(S10/J10,0)*12 -> 30963.963 | U10: =IF(T10<=40000,0, IF(T10<=55000,(T10-40000)*10%, IF(T10<=70000,(T10-55000)*15%+1500, IF(T10<=200000,(T10-70000)*20%+1500+2250, IF(T10<=400000,(T10-200000)*22.5%+1500+2250+26000, IF(T10<=600000,(T10-400000)*25%+1500+2250+26000+45000, IF(AND(T10>600000,T10<=1200000),(T10-400000)*25%+1500+2250+26000+45000 +IFERROR(LOOKUP(T10,{600001;700001;800001;900001},{4000;6750;10250;15250}),0),IF(T10>1200000,((T10-1200000)*27.5%)+300000,0) ))))))) -> 0 | V10: =U10/12*J10 -> 0 | W10: =+'11-2025'!$S10-'11-2025'!$V10+'11-2025'!$R10 -> 4246.9969 | X10: =IFERROR(W10/30,"") -> 141.56656 | Y10: 0 | Z10: =IFERROR(+'11-2025'!$X10*'11-2025'!$Y10,"") -> 0 | AA10: 0 | AB10: =IFERROR(+'11-2025'!$X10*'11-2025'!$AA10,"") -> 0 | AC10: 0 | AD10: =IFERROR(+'11-2025'!$X10*'11-2025'!$AC10,"") -> 0 | AE10: 0 | AF10: =IFERROR(+'11-2025'!$X10*'11-2025'!$AE10,"") -> 0 | AG10: 0 | AH10: =IFERROR(+'11-2025'!$X10*'11-2025'!$AG10,"") -> 0 | AI10: 0 | AJ10: =IFERROR('11-2025'!$Z10+'11-2025'!$AB10+'11-2025'!$AD10+'11-2025'!$AF10+'11-2025'!$AH10+'11-2025'!$AI10,"") -> 0 | AK10: =IFERROR('11-2025'!$W10-'11-2025'!$AJ10,"") -> 4246.9969 | AM10: 500 | AO10: 140 | AP10: 283.13313 | AR10: 0 | AS10: 0 | AT10: 0 | AU10: 0 | AV10: 0 | AW10: 0 | AX10: 275 | AY10: 215 | AZ10: 0 | BA10: 0 | BB10: 165 | BC10: 0 | BD10: 0 | BE10: 0 | BF10: 115 | BG10: 0 | BH10: 0 | BI10: 35 | BJ10: =BD10+BC10+BB10+BA10+AZ10+AY10+AX10+AW10+AV10+AU10+AT10+AS10+AR10+BE10+BF10+BG10+BH10+BI10 -> 805 | BK10: =BJ10+AM10+AL10+'11-2025'!$N10+AN10+AO10 -> 6102.39 | BL10: ='11-2025'!$O10 -> 3730.8462 | BM10: =BL10*18.75% -> 699.53365 | BN10: =BL10*11% -> 410.39308 | BO10: =+R10 -> 1666.6667 | BP10: =IF(BK10-BN10-BO10<0,0,BK10-BN10-BO10) -> 4025.3303 | BQ10: =IFERROR(BP10/'11-2025'!$J10,0)*12 -> 48303.963 | BR10: =IF(BQ10<=40000,0, IF(BQ10<=55000,(BQ10-40000)*10%, IF(BQ10<=70000,(BQ10-55000)*15%+1500, IF(BQ10<=200000,(BQ10-70000)*20%+1500+2250, IF(BQ10<=400000,(BQ10-200000)*22.5%+1500+2250+26000, IF(BQ10<=600000,(BQ10-400000)*25%+1500+2250+26000+45000, IF(AND(BQ10>600000,BQ10<=1200000),(BQ10-400000)*25%+1500+2250+26000+45000 +IFERROR(LOOKUP(BQ10,{600001;700001;800001;900001},{4000;6750;10250;15250}),0),IF(BQ10>1200000,((BQ10-1200000)*27.5%)+300000,0) ))))))) -> 830.39631 | BS10: =(BR10/12*'11-2025'!$J10) -> 69.199692 | BT10: =BS10-'11-2025'!$V10 -> 69.199692 | BU10: =IFERROR(+'11-2025'!$W10+AL10+AM10+BJ10-'11-2025'!$AJ10-BT10+AN10+AO10,"")-AL10+AP10+AQ10 -> 5905.9304 | BV10: عدد 2 يوم بدل حضور يوم الجمعه + مكافأة تحرير إنذارات شركة وسيلة | BX10: =+BU10-BW10 -> 5905.9304 | BY10: فيزا
A11: 64 | B11: تريز سامى رزق شحاته | C11: 20أ القاهرة | D11: الادارى | E11: الموارد البشرية | F11: مدير موارد بشرية | G11: 45081 | I11: 28712200101702 | J11: 1 | K11: 8997.18 | N11: =SUM('11-2025'!$K11:$M11) -> 8997.18 | O11: 5230 | P11: =O11*18.75% -> 980.625 | Q11: =O11*11% -> 575.3 | R11: 1666.6667 | S11: =IF(N11-Q11-R11<0,0,N11-Q11-R11) -> 6755.2133 | T11: =IFERROR(S11/J11,0)*12 -> 81062.56 | U11: =IF(T11<=40000,0, IF(T11<=55000,(T11-40000)*10%, IF(T11<=70000,(T11-55000)*15%+1500, IF(T11<=200000,(T11-70000)*20%+1500+2250, IF(T11<=400000,(T11-200000)*22.5%+1500+2250+26000, IF(T11<=600000,(T11-400000)*25%+1500+2250+26000+45000, IF(AND(T11>600000,T11<=1200000),(T11-400000)*25%+1500+2250+26000+45000 +IFERROR(LOOKUP(T11,{600001;700001;800001;900001},{4000;6750;10250;15250}),0),IF(T11>1200000,((T11-1200000)*27.5%)+300000,0) ))))))) -> 5962.512 | V11: =U11/12*J11 -> 496.876 | W11: =+'11-2025'!$S11-'11-2025'!$V11+'11-2025'!$R11 -> 7925.004 | X11: =IFERROR(W11/30,"") -> 264.1668 | Y11: 0 | Z11: =IFERROR(+'11-2025'!$X11*'11-2025'!$Y11,"") -> 0 | AA11: 0 | AB11: =IFERROR(+'11-2025'!$X11*'11-2025'!$AA11,"") -> 0 | AC11: 1.5 | AD11: =IFERROR(+'11-2025'!$X11*'11-2025'!$AC11,"") -> 396.2502 | AE11: 0 | AF11: =IFERROR(+'11-2025'!$X11*'11-2025'!$AE11,"") -> 0 | AG11: 2.25 | AH11: =IFERROR(+'11-2025'!$X11*'11-2025'!$AG11,"") -> 594.3753 | AI11: 0 | AJ11: =IFERROR('11-2025'!$Z11+'11-2025'!$AB11+'11-2025'!$AD11+'11-2025'!$AF11+'11-2025'!$AH11+'11-2025'!$AI11,"") -> 990.6255 | AK11: =IFERROR('11-2025'!$W11-'11-2025'!$AJ11,"") -> 6934.3785 | AO11: 0 | AR11: 0 | AS11: 0 | AT11: 0 | AU11: 0 | AV11: 0 | AW11: 0 | AX11: 0 | AY11: 0 | AZ11: 0 | BA11: 0 | BB11: 0 | BC11: 0 | BD11: 0 | BE11: 0 | BF11: 0 | BG11: 0 | BH11: 0 | BI11: 0 | BJ11: =BD11+BC11+BB11+BA11+AZ11+AY11+AX11+AW11+AV11+AU11+AT11+AS11+AR11+BE11+BF11+BG11+BH11+BI11 -> 0 | BK11: =BJ11+AM11+AL11+'11-2025'!$N11+AN11+AO11 -> 8997.18 | BL11: ='11-2025'!$O11 -> 5230 | BM11: =BL11*18.75% -> 980.625 | BN11: =BL11*11% -> 575.3 | BO11: =+R11 -> 1666.6667 | BP11: =IF(BK11-BN11-BO11<0,0,BK11-BN11-BO11) -> 6755.2133 | BQ11: =IFERROR(BP11/'11-2025'!$J11,0)*12 -> 81062.56 | BR11: =IF(BQ11<=40000,0, IF(BQ11<=55000,(BQ11-40000)*10%, IF(BQ11<=70000,(BQ11-55000)*15%+1500, IF(BQ11<=200000,(BQ11-70000)*20%+1500+2250, IF(BQ11<=400000,(BQ11-200000)*22.5%+1500+2250+26000, IF(BQ11<=600000,(BQ11-400000)*25%+1500+2250+26000+45000, IF(AND(BQ11>600000,BQ11<=1200000),(BQ11-400000)*25%+1500+2250+26000+45000 +IFERROR(LOOKUP(BQ11,{600001;700001;800001;900001},{4000;6750;10250;15250}),0),IF(BQ11>1200000,((BQ11-1200000)*27.5%)+300000,0) ))))))) -> 5962.512 | BS11: =(BR11/12*'11-2025'!$J11) -> 496.876 | BT11: =BS11-'11-2025'!$V11 -> 0 | BU11: =IFERROR(+'11-2025'!$W11+AL11+AM11+BJ11-'11-2025'!$AJ11-BT11+AN11+AO11,"")-AL11+AP11+AQ11 -> 6934.3785 | BX11: =+BU11-BW11 -> 6934.3785 | BY11: فيزا
A12: 71 | B12: ندى محمد سعد محمد | C12: 20أ القاهرة | D12: التحصيل | E12: شركة حالا | F12: رئيس فريق عمل | G12: 45081 | I12: 30110042101308 | J12: 1 | K12: 3214.5 | N12: =SUM('11-2025'!$K12:$M12) -> 3214.5 | O12: 4250 | P12: =O12*18.75% -> 796.875 | Q12: =O12*11% -> 467.5 | R12: 1666.6667 | S12: =IF(N12-Q12-R12<0,0,N12-Q12-R12) -> 1080.3333 | T12: =IFERROR(S12/J12,0)*12 -> 12964 | U12: =IF(T12<=40000,0, IF(T12<=55000,(T12-40000)*10%, IF(T12<=70000,(T12-55000)*15%+1500, IF(T12<=200000,(T12-70000)*20%+1500+2250, IF(T12<=400000,(T12-200000)*22.5%+1500+2250+26000, IF(T12<=600000,(T12-400000)*25%+1500+2250+26000+45000, IF(AND(T12>600000,T12<=1200000),(T12-400000)*25%+1500+2250+26000+45000 +IFERROR(LOOKUP(T12,{600001;700001;800001;900001},{4000;6750;10250;15250}),0),IF(T12>1200000,((T12-1200000)*27.5%)+300000,0) ))))))) -> 0 | V12: =U12/12*J12 -> 0 | W12: =+'11-2025'!$S12-'11-2025'!$V12+'11-2025'!$R12 -> 2747 | X12: =IFERROR(W12/30,"") -> 91.566667 | Y12: 0 | Z12: =IFERROR(+'11-2025'!$X12*'11-2025'!$Y12,"") -> 0 | AA12: 0 | AB12: =IFERROR(+'11-2025'!$X12*'11-2025'!$AA12,"") -> 0 | AC12: 0 | AD12: =IFERROR(+'11-2025'!$X12*'11-2025'!$AC12,"") -> 0 | AE12: 0 | AF12: =IFERROR(+'11-2025'!$X12*'11-2025'!$AE12,"") -> 0 | AG12: 0 | AH12: =IFERROR(+'11-2025'!$X12*'11-2025'!$AG12,"") -> 0 | AI12: 1500 | AJ12: =IFERROR('11-2025'!$Z12+'11-2025'!$AB12+'11-2025'!$AD12+'11-2025'!$AF12+'11-2025'!$AH12+'11-2025'!$AI12,"") -> 1500 | AK12: =IFERROR('11-2025'!$W12-'11-2025'!$AJ12,"") -> 1247 | AM12: 500 | AO12: 20 | AR12: 0 | AS12: 2753.735 | AT12: 0 | AU12: 0 | AV12: 0 | AW12: 0 | AX12: 0 | AY12: 0 | AZ12: 0 | BA12: 0 | BB12: 0 | BC12: 0 | BD12: 0 | BE12: 0 | BF12: 0 | BG12: 0 | BH12: 0 | BI12: 0 | BJ12: =BD12+BC12+BB12+BA12+AZ12+AY12+AX12+AW12+AV12+AU12+AT12+AS12+AR12+BE12+BF12+BG12+BH12+BI12 -> 2753.735 | BK12: =BJ12+AM12+AL12+'11-2025'!$N12+AN12+AO12 -> 6488.235 | BL12: ='11-2025'!$O12 -> 4250 | BM12: =BL12*18.75% -> 796.875 | BN12: =BL12*11% -> 467.5 | BO12: =+R12 -> 1666.6667 | BP12: =IF(BK12-BN12-BO12<0,0,BK12-BN12-BO12) -> 4354.0683 | BQ12: =IFERROR(BP12/'11-2025'!$J12,0)*12 -> 52248.82 | BR12: =IF(BQ12<=40000,0, IF(BQ12<=55000,(BQ12-40000)*10%, IF(BQ12<=70000,(BQ12-55000)*15%+1500, IF(BQ12<=200000,(BQ12-70000)*20%+1500+2250, IF(BQ12<=400000,(BQ12-200000)*22.5%+1500+2250+26000, IF(BQ12<=600000,(BQ12-400000)*25%+1500+2250+26000+45000, IF(AND(BQ12>600000,BQ12<=1200000),(BQ12-400000)*25%+1500+2250+26000+45000 +IFERROR(LOOKUP(BQ12,{600001;700001;800001;900001},{4000;6750;10250;15250}),0),IF(BQ12>1200000,((BQ12-1200000)*27.5%)+300000,0) ))))))) -> 1224.882 | BS12: =(BR12/12*'11-2025'!$J12) -> 102.0735 | BT12: =BS12-'11-2025'!$V12 -> 102.0735 | BU12: =IFERROR(+'11-2025'!$W12+AL12+AM12+BJ12-'11-2025'!$AJ12-BT12+AN12+AO12,"")-AL12+AP12+AQ12 -> 4418.6615 | BV12: مكافاة اشراف | BX12: =+BU12-BW12 -> 4418.6615 | BY12: فيزا
A13: 83 | B13: حبيبه احمد سلطان منصور عويس | C13: 20أ القاهرة | D13: التحصيل | E13: شركة مانى فيللوز | F13: مشرف تحصيل | G13: 45111 | I13: 30312060105762 | J13: 1 | K13: 4000 | N13: =SUM('11-2025'!$K13:$M13) -> 4000 | O13: 4000 | P13: =O13*18.75% -> 750 | Q13: =O13*11% -> 440 | R13: 1666.6667 | S13: =IF(N13-Q13-R13<0,0,N13-Q13-R13) -> 1893.3333 | T13: =IFERROR(S13/J13,0)*12 -> 22720 | U13: =IF(T13<=40000,0, IF(T13<=55000,(T13-40000)*10%, IF(T13<=70000,(T13-55000)*15%+1500, IF(T13<=200000,(T13-70000)*20%+1500+2250, IF(T13<=400000,(T13-200000)*22.5%+1500+2250+26000, IF(T13<=600000,(T13-400000)*25%+1500+2250+26000+45000, IF(AND(T13>600000,T13<=1200000),(T13-400000)*25%+1500+2250+26000+45000 +IFERROR(LOOKUP(T13,{600001;700001;800001;900001},{4000;6750;10250;15250}),0),IF(T13>1200000,((T13-1200000)*27.5%)+300000,0) ))))))) -> 0 | V13: =U13/12*J13 -> 0 | W13: =+'11-2025'!$S13-'11-2025'!$V13+'11-2025'!$R13 -> 3560 | X13: =IFERROR(W13/30,"") -> 118.66667 | Y13: 0 | Z13: =IFERROR(+'11-2025'!$X13*'11-2025'!$Y13,"") -> 0 | AA13: 0 | AB13: =IFERROR(+'11-2025'!$X13*'11-2025'!$AA13,"") -> 0 | AC13: 0 | AD13: =IFERROR(+'11-2025'!$X13*'11-2025'!$AC13,"") -> 0 | AE13: 0 | AF13: =IFERROR(+'11-2025'!$X13*'11-2025'!$AE13,"") -> 0 | AG13: 0 | AH13: =IFERROR(+'11-2025'!$X13*'11-2025'!$AG13,"") -> 0 | AI13: 0 | AJ13: =IFERROR('11-2025'!$Z13+'11-2025'!$AB13+'11-2025'!$AD13+'11-2025'!$AF13+'11-2025'!$AH13+'11-2025'!$AI13,"") -> 0 | AK13: =IFERROR('11-2025'!$W13-'11-2025'!$AJ13,"") -> 3560 | AO13: 20 | AR13: 0 | AS13: 0 | AT13: 0 | AU13: 0 | AV13: 0 | AW13: 4040.3225 | AX13: 0 | AY13: 0 | AZ13: 0 | BA13: 0 | BB13: 0 | BC13: 0 | BD13: 0 | BE13: 0 | BF13: 0 | BG13: 0 | BH13: 0 | BI13: 0 | BJ13: =BD13+BC13+BB13+BA13+AZ13+AY13+AX13+AW13+AV13+AU13+AT13+AS13+AR13+BE13+BF13+BG13+BH13+BI13 -> 4040.3225 | BK13: =BJ13+AM13+AL13+'11-2025'!$N13+AN13+AO13 -> 8060.3225 | BL13: ='11-2025'!$O13 -> 4000 | BM13: =BL13*18.75% -> 750 | BN13: =BL13*11% -> 440 | BO13: =+R13 -> 1666.6667 | BP13: =IF(BK13-BN13-BO13<0,0,BK13-BN13-BO13) -> 5953.6558 | BQ13: =IFERROR(BP13/'11-2025'!$J13,0)*12 -> 71443.87 | BR13: =IF(BQ13<=40000,0, IF(BQ13<=55000,(BQ13-40000)*10%, IF(BQ13<=70000,(BQ13-55000)*15%+1500, IF(BQ13<=200000,(BQ13-70000)*20%+1500+2250, IF(BQ13<=400000,(BQ13-200000)*22.5%+1500+2250+26000, IF(BQ13<=600000,(BQ13-400000)*25%+1500+2250+26000+45000, IF(AND(BQ13>600000,BQ13<=1200000),(BQ13-400000)*25%+1500+2250+26000+45000 +IFERROR(LOOKUP(BQ13,{600001;700001;800001;900001},{4000;6750;10250;15250}),0),IF(BQ13>1200000,((BQ13-1200000)*27.5%)+300000,0) ))))))) -> 4038.774 | BS13: =(BR13/12*'11-2025'!$J13) -> 336.5645 | BT13: =BS13-'11-2025'!$V13 -> 336.5645 | BU13: =IFERROR(+'11-2025'!$W13+AL13+AM13+BJ13-'11-2025'!$AJ13-BT13+AN13+AO13,"")-AL13+AP13+AQ13 -> 7283.758 | BX13: =+BU13-BW13 -> 7283.758 | BY13: فيزا
A14: 97 | B14: ندى محمد محمود عبد المقصود | C14: 20أ القاهرة | D14: التحصيل | E14: بنك الإسكندرية | F14: وكيل تحصيل هاتفى | G14: 45811 | H14: 45954 | I14: 30106051400523 | J14: 1 | K14: 2500 | N14: =SUM('11-2025'!$K14:$M14) -> 2500 | P14: =O14*18.75% -> 0 | Q14: =O14*11% -> 0 | R14: 1666.6667 | S14: =IF(N14-Q14-R14<0,0,N14-Q14-R14) -> 833.33333 | T14: =IFERROR(S14/J14,0)*12 -> 10000 | U14: =IF(T14<=40000,0, IF(T14<=55000,(T14-40000)*10%, IF(T14<=70000,(T14-55000)*15%+1500, IF(T14<=200000,(T14-70000)*20%+1500+2250, IF(T14<=400000,(T14-200000)*22.5%+1500+2250+26000, IF(T14<=600000,(T14-400000)*25%+1500+2250+26000+45000, IF(AND(T14>600000,T14<=1200000),(T14-400000)*25%+1500+2250+26000+45000 +IFERROR(LOOKUP(T14,{600001;700001;800001;900001},{4000;6750;10250;15250}),0),IF(T14>1200000,((T14-1200000)*27.5%)+300000,0) ))))))) -> 0 | V14: =U14/12*J14 -> 0 | W14: =+'11-2025'!$S14-'11-2025'!$V14+'11-2025'!$R14 -> 2500 | X14: =IFERROR(W14/30,"") -> 83.333333 | Z14: =IFERROR(+'11-2025'!$X14*'11-2025'!$Y14,"") -> 0 | AA14: 0 | AB14: =IFERROR(+'11-2025'!$X14*'11-2025'!$AA14,"") -> 0 | AC14: 30 | AD14: =IFERROR(+'11-2025'!$X14*'11-2025'!$AC14,"") -> 2500 | AE14: 0 | AF14: =IFERROR(+'11-2025'!$X14*'11-2025'!$AE14,"") -> 0 | AH14: =IFERROR(+'11-2025'!$X14*'11-2025'!$AG14,"") -> 0 | AI14: 0 | AJ14: =IFERROR('11-2025'!$Z14+'11-2025'!$AB14+'11-2025'!$AD14+'11-2025'!$AF14+'11-2025'!$AH14+'11-2025'!$AI14,"") -> 2500 | AK14: =IFERROR('11-2025'!$W14-'11-2025'!$AJ14,"") -> 0 | AR14: 0 | AS14: 0 | AT14: 0 | AU14: 0 | AV14: 0 | AW14: 0 | AX14: 0 | AY14: 0 | AZ14: 0 | BA14: 0 | BB14: 0 | BC14: 0 | BD14: 0 | BE14: 0 | BF14: 0 | BG14: 0 | BH14: 0 | BI14: 0 | BJ14: =BD14+BC14+BB14+BA14+AZ14+AY14+AX14+AW14+AV14+AU14+AT14+AS14+AR14+BE14+BF14+BG14+BH14+BI14 -> 0 | BK14: =BJ14+AM14+AL14+'11-2025'!$N14+AN14+AO14 -> 2500 | BL14: ='11-2025'!$O14 -> 0 | BM14: =BL14*18.75% -> 0 | BN14: =BL14*11% -> 0 | BO14: =+R14 -> 1666.6667 | BP14: =IF(BK14-BN14-BO14<0,0,BK14-BN14-BO14) -> 833.33333 | BQ14: =IFERROR(BP14/'11-2025'!$J14,0)*12 -> 10000 | BR14: =IF(BQ14<=40000,0, IF(BQ14<=55000,(BQ14-40000)*10%, IF(BQ14<=70000,(BQ14-55000)*15%+1500, IF(BQ14<=200000,(BQ14-70000)*20%+1500+2250, IF(BQ14<=400000,(BQ14-200000)*22.5%+1500+2250+26000, IF(BQ14<=600000,(BQ14-400000)*25%+1500+2250+26000+45000, IF(AND(BQ14>600000,BQ14<=1200000),(BQ14-400000)*25%+1500+2250+26000+45000 +IFERROR(LOOKUP(BQ14,{600001;700001;800001;900001},{4000;6750;10250;15250}),0),IF(BQ14>1200000,((BQ14-1200000)*27.5%)+300000,0) ))))))) -> 0 | BS14: =(BR14/12*'11-2025'!$J14) -> 0 | BT14: =BS14-'11-2025'!$V14 -> 0 | BU14: =IFERROR(+'11-2025'!$W14+AL14+AM14+BJ14-'11-2025'!$AJ14-BT14+AN14+AO14,"")-AL14+AP14+AQ14 -> 0 | BX14: =+BU14-BW14 -> 0
A15: 119 | B15: مصطفى جميل عبد الفتاح محمد شاهين | C15: 20أ القاهرة | D15: التحصيل | E15: شركة سفن | F15: رئيس فريق عمل | G15: 45326 | I15: 30302090103319 | J15: 1 | K15: 3750.46 | N15: =SUM('11-2025'!$K15:$M15) -> 3750.46 | O15: 4576.9231 | P15: =O15*18.75% -> 858.17308 | Q15: =O15*11% -> 503.46154 | R15: 1666.6667 | S15: =IF(N15-Q15-R15<0,0,N15-Q15-R15) -> 1580.3318 | T15: =IFERROR(S15/J15,0)*12 -> 18963.982 | U15: =IF(T15<=40000,0, IF(T15<=55000,(T15-40000)*10%, IF(T15<=70000,(T15-55000)*15%+1500, IF(T15<=200000,(T15-70000)*20%+1500+2250, IF(T15<=400000,(T15-200000)*22.5%+1500+2250+26000, IF(T15<=600000,(T15-400000)*25%+1500+2250+26000+45000, IF(AND(T15>600000,T15<=1200000),(T15-400000)*25%+1500+2250+26000+45000 +IFERROR(LOOKUP(T15,{600001;700001;800001;900001},{4000;6750;10250;15250}),0),IF(T15>1200000,((T15-1200000)*27.5%)+300000,0) ))))))) -> 0 | V15: =U15/12*J15 -> 0 | W15: =+'11-2025'!$S15-'11-2025'!$V15+'11-2025'!$R15 -> 3246.9985 | X15: =IFERROR(W15/30,"") -> 108.23328 | Y15: 0 | Z15: =IFERROR(+'11-2025'!$X15*'11-2025'!$Y15,"") -> 0 | AA15: 0 | AB15: =IFERROR(+'11-2025'!$X15*'11-2025'!$AA15,"") -> 0 | AC15: 0 | AD15: =IFERROR(+'11-2025'!$X15*'11-2025'!$AC15,"") -> 0 | AE15: 0 | AF15: =IFERROR(+'11-2025'!$X15*'11-2025'!$AE15,"") -> 0 | AG15: 0 | AH15: =IFERROR(+'11-2025'!$X15*'11-2025'!$AG15,"") -> 0 | AI15: 2500 | AJ15: =IFERROR('11-2025'!$Z15+'11-2025'!$AB15+'11-2025'!$AD15+'11-2025'!$AF15+'11-2025'!$AH15+'11-2025'!$AI15,"") -> 2500 | AK15: =IFERROR('11-2025'!$W15-'11-2025'!$AJ15,"") -> 746.99846 | AM15: 500 | AO15: 60 | AR15: 0 | AS15: 0 | AT15: 3557.216 | AU15: 0 | AV15: 0 | AW15: 0 | AX15: 0 | AY15: 0 | AZ15: 0 | BA15: 0 | BB15: 0 | BC15: 0 | BD15: 0 | BE15: 0 | BF15: 0 | BG15: 1289 | BH15: 0 | BI15: 0 | BJ15: =BD15+BC15+BB15+BA15+AZ15+AY15+AX15+AW15+AV15+AU15+AT15+AS15+AR15+BE15+BF15+BG15+BH15+BI15 -> 4846.216 | BK15: =BJ15+AM15+AL15+'11-2025'!$N15+AN15+AO15 -> 9156.676 | BL15: ='11-2025'!$O15 -> 4576.9231 | BM15: =BL15*18.75% -> 858.17308 | BN15: =BL15*11% -> 503.46154 | BO15: =+R15 -> 1666.6667 | BP15: =IF(BK15-BN15-BO15<0,0,BK15-BN15-BO15) -> 6986.5478 | BQ15: =IFERROR(BP15/'11-2025'!$J15,0)*12 -> 83838.573 | BR15: =IF(BQ15<=40000,0, IF(BQ15<=55000,(BQ15-40000)*10%, IF(BQ15<=70000,(BQ15-55000)*15%+1500, IF(BQ15<=200000,(BQ15-70000)*20%+1500+2250, IF(BQ15<=400000,(BQ15-200000)*22.5%+1500+2250+26000, IF(BQ15<=600000,(BQ15-400000)*25%+1500+2250+26000+45000, IF(AND(BQ15>600000,BQ15<=1200000),(BQ15-400000)*25%+1500+2250+26000+45000 +IFERROR(LOOKUP(BQ15,{600001;700001;800001;900001},{4000;6750;10250;15250}),0),IF(BQ15>1200000,((BQ15-1200000)*27.5%)+300000,0) ))))))) -> 6517.7147 | BS15: =(BR15/12*'11-2025'!$J15) -> 543.14289 | BT15: =BS15-'11-2025'!$V15 -> 543.14289 | BU15: =IFERROR(+'11-2025'!$W15+AL15+AM15+BJ15-'11-2025'!$AJ15-BT15+AN15+AO15,"")-AL15+AP15+AQ15 -> 5610.0716 | BV15: مكافاة اشراف | BX15: =+BU15-BW15 -> 5610.0716 | BY15: فيزا
A16: 129 | B16: نانسى يوسف عزيز يوسف | C16: المنصورة | D16: الادارى | E16: الشئون القانونية | F16: نائب مدير الإدارة القانونية | G16: 45150 | I16: 28908081201843 | J16: 1 | K16: 5322.38 | N16: =SUM('11-2025'!$K16:$M16) -> 5322.38 | O16: 5230.7692 | P16: =O16*18.75% -> 980.76923 | Q16: =O16*11% -> 575.38462 | R16: 1666.6667 | S16: =IF(N16-Q16-R16<0,0,N16-Q16-R16) -> 3080.3287 | T16: =IFERROR(S16/J16,0)*12 -> 36963.945 | U16: =IF(T16<=40000,0, IF(T16<=55000,(T16-40000)*10%, IF(T16<=70000,(T16-55000)*15%+1500, IF(T16<=200000,(T16-70000)*20%+1500+2250, IF(T16<=400000,(T16-200000)*22.5%+1500+2250+26000, IF(T16<=600000,(T16-400000)*25%+1500+2250+26000+45000, IF(AND(T16>600000,T16<=1200000),(T16-400000)*25%+1500+2250+26000+45000 +IFERROR(LOOKUP(T16,{600001;700001;800001;900001},{4000;6750;10250;15250}),0),IF(T16>1200000,((T16-1200000)*27.5%)+300000,0) ))))))) -> 0 | V16: =U16/12*J16 -> 0 | W16: =+'11-2025'!$S16-'11-2025'!$V16+'11-2025'!$R16 -> 4746.9954 | X16: =IFERROR(W16/30,"") -> 158.23318 | Y16: 0 | Z16: =IFERROR(+'11-2025'!$X16*'11-2025'!$Y16,"") -> 0 | AA16: 0 | AB16: =IFERROR(+'11-2025'!$X16*'11-2025'!$AA16,"") -> 0 | AC16: 0 | AD16: =IFERROR(+'11-2025'!$X16*'11-2025'!$AC16,"") -> 0 | AE16: 0 | AF16: =IFERROR(+'11-2025'!$X16*'11-2025'!$AE16,"") -> 0 | AG16: 0 | AH16: =IFERROR(+'11-2025'!$X16*'11-2025'!$AG16,"") -> 0 | AI16: 0 | AJ16: =IFERROR('11-2025'!$Z16+'11-2025'!$AB16+'11-2025'!$AD16+'11-2025'!$AF16+'11-2025'!$AH16+'11-2025'!$AI16,"") -> 0 | AK16: =IFERROR('11-2025'!$W16-'11-2025'!$AJ16,"") -> 4746.9954 | AO16: 0 | AR16: 0 | AS16: 0 | AT16: 0 | AU16: 0 | AV16: 0 | AW16: 0 | AX16: 0 | AY16: 0 | AZ16: 0 | BA16: 385 | BB16: 0 | BC16: 0 | BD16: 0 | BE16: 0 | BF16: 0 | BG16: 0 | BH16: 0 | BI16: 0 | BJ16: =BD16+BC16+BB16+BA16+AZ16+AY16+AX16+AW16+AV16+AU16+AT16+AS16+AR16+BE16+BF16+BG16+BH16+BI16 -> 385 | BK16: =BJ16+AM16+AL17+'11-2025'!$N16+AN16+AO16 -> 5707.38 | BL16: ='11-2025'!$O16 -> 5230.7692 | BM16: =BL16*18.75% -> 980.76923 | BN16: =BL16*11% -> 575.38462 | BO16: =+R16 -> 1666.6667 | BP16: =IF(BK16-BN16-BO16<0,0,BK16-BN16-BO16) -> 3465.3287 | BQ16: =IFERROR(BP16/'11-2025'!$J16,0)*12 -> 41583.945 | BR16: =IF(BQ16<=40000,0, IF(BQ16<=55000,(BQ16-40000)*10%, IF(BQ16<=70000,(BQ16-55000)*15%+1500, IF(BQ16<=200000,(BQ16-70000)*20%+1500+2250, IF(BQ16<=400000,(BQ16-200000)*22.5%+1500+2250+26000, IF(BQ16<=600000,(BQ16-400000)*25%+1500+2250+26000+45000, IF(AND(BQ16>600000,BQ16<=1200000),(BQ16-400000)*25%+1500+2250+26000+45000 +IFERROR(LOOKUP(BQ16,{600001;700001;800001;900001},{4000;6750;10250;15250}),0),IF(BQ16>1200000,((BQ16-1200000)*27.5%)+300000,0) ))))))) -> 158.39446 | BS16: =(BR16/12*'11-2025'!$J16) -> 13.199538 | BT16: =BS16-'11-2025'!$V16 -> 13.199538 | BU16: =IFERROR(+'11-2025'!$W16+AL16+AM16+BJ16-'11-2025'!$AJ16-BT16+AN16+AO16,"")-AL16+AP16+AQ16 -> 5118.7958 | BX16: =+BU16-BW16 -> 5118.7958 | BY16: فيزا
A17: 131 | B17: امانى طارق إبراهيم عبد الحميد | C17: المنصورة | D17: الادارى | E17: منسقى البيانات | F17: رئيس فريق عمل | G17: 45145 | I17: 29501011262064 | J17: 1 | K17: 4644.73 | N17: =SUM('11-2025'!$K17:$M17) -> 4644.73 | O17: 3615.7692 | P17: =O17*18.75% -> 677.95673 | Q17: =O17*11% -> 397.73462 | R17: 1666.6667 | S17: =IF(N17-Q17-R17<0,0,N17-Q17-R17) -> 2580.3287 | T17: =IFERROR(S17/J17,0)*12 -> 30963.945 | U17: =IF(T17<=40000,0, IF(T17<=55000,(T17-40000)*10%, IF(T17<=70000,(T17-55000)*15%+1500, IF(T17<=200000,(T17-70000)*20%+1500+2250, IF(T17<=400000,(T17-200000)*22.5%+1500+2250+26000, IF(T17<=600000,(T17-400000)*25%+1500+2250+26000+45000, IF(AND(T17>600000,T17<=1200000),(T17-400000)*25%+1500+2250+26000+45000 +IFERROR(LOOKUP(T17,{600001;700001;800001;900001},{4000;6750;10250;15250}),0),IF(T17>1200000,((T17-1200000)*27.5%)+300000,0) ))))))) -> 0 | V17: =U17/12*J17 -> 0 | W17: =+'11-2025'!$S17-'11-2025'!$V17+'11-2025'!$R17 -> 4246.9954 | X17: =IFERROR(W17/30,"") -> 141.56651 | Y17: 0 | Z17: =IFERROR(+'11-2025'!$X17*'11-2025'!$Y17,"") -> 0 | AA17: 0 | AB17: =IFERROR(+'11-2025'!$X17*'11-2025'!$AA17,"") -> 0 | AC17: 0 | AD17: =IFERROR(+'11-2025'!$X17*'11-2025'!$AC17,"") -> 0 | AE17: 0 | AF17: =IFERROR(+'11-2025'!$X17*'11-2025'!$AE17,"") -> 0 | AG17: 0 | AH17: =IFERROR(+'11-2025'!$X17*'11-2025'!$AG17,"") -> 0 | AI17: 0 | AJ17: =IFERROR('11-2025'!$Z17+'11-2025'!$AB17+'11-2025'!$AD17+'11-2025'!$AF17+'11-2025'!$AH17+'11-2025'!$AI17,"") -> 0 | AK17: =IFERROR('11-2025'!$W17-'11-2025'!$AJ17,"") -> 4246.9954 | AO17: 80 | AR17: 0 | AS17: 0 | AT17: 0 | AU17: 0 | AV17: 0 | AW17: 0 | AX17: 0 | AY17: 0 | AZ17: 0 | BA17: 0 | BB17: 0 | BC17: 0 | BD17: 0 | BE17: 0 | BF17: 0 | BG17: 0 | BH17: 0 | BI17: 0 | BJ17: =BD17+BC17+BB17+BA17+AZ17+AY17+AX17+AW17+AV17+AU17+AT17+AS17+AR17+BE17+BF17+BG17+BH17+BI17 -> 0 | BK17: =BJ17+AM17+AL18+'11-2025'!$N17+AN17+AO17 -> 4724.73 | BL17: ='11-2025'!$O17 -> 3615.7692 | BM17: =BL17*18.75% -> 677.95673 | BN17: =BL17*11% -> 397.73462 | BO17: =+R17 -> 1666.6667 | BP17: =IF(BK17-BN17-BO17<0,0,BK17-BN17-BO17) -> 2660.3287 | BQ17: =IFERROR(BP17/'11-2025'!$J17,0)*12 -> 31923.945 | BR17: =IF(BQ17<=40000,0, IF(BQ17<=55000,(BQ17-40000)*10%, IF(BQ17<=70000,(BQ17-55000)*15%+1500, IF(BQ17<=200000,(BQ17-70000)*20%+1500+2250, IF(BQ17<=400000,(BQ17-200000)*22.5%+1500+2250+26000, IF(BQ17<=600000,(BQ17-400000)*25%+1500+2250+26000+45000, IF(AND(BQ17>600000,BQ17<=1200000),(BQ17-400000)*25%+1500+2250+26000+45000 +IFERROR(LOOKUP(BQ17,{600001;700001;800001;900001},{4000;6750;10250;15250}),0),IF(BQ17>1200000,((BQ17-1200000)*27.5%)+300000,0) ))))))) -> 0 | BS17: =(BR17/12*'11-2025'!$J17) -> 0 | BT17: =BS17-'11-2025'!$V17 -> 0 | BU17: =IFERROR(+'11-2025'!$W17+AL17+AM17+BJ17-'11-2025'!$AJ17-BT17+AN17+AO17,"")-AL17+AP17+AQ17 -> 4326.9954 | BX17: =+BU17-BW17 -> 4326.9954 | BY17: فيزا
A18: 133 | B18: نادين عماد منصور محمد | C18: المنصورة | D18: التحصيل | E18: شركة تنمية | F18: وكيل تحصيل هاتفى | G18: 45582 | I18: 30106141202127 | J18: 1 | K18: 4000 | N18: =SUM('11-2025'!$K18:$M18) -> 4000 | O18: 4000 | P18: =O18*18.75% -> 750 | Q18: =O18*11% -> 440 | R18: 1666.6667 | S18: =IF(N18-Q18-R18<0,0,N18-Q18-R18) -> 1893.3333 | T18: =IFERROR(S18/J18,0)*12 -> 22720 | U18: =IF(T18<=40000,0, IF(T18<=55000,(T18-40000)*10%, IF(T18<=70000,(T18-55000)*15%+1500, IF(T18<=200000,(T18-70000)*20%+1500+2250, IF(T18<=400000,(T18-200000)*22.5%+1500+2250+26000, IF(T18<=600000,(T18-400000)*25%+1500+2250+26000+45000, IF(AND(T18>600000,T18<=1200000),(T18-400000)*25%+1500+2250+26000+45000 +IFERROR(LOOKUP(T18,{600001;700001;800001;900001},{4000;6750;10250;15250}),0),IF(T18>1200000,((T18-1200000)*27.5%)+300000,0) ))))))) -> 0 | V18: =U18/12*J18 -> 0 | W18: =+'11-2025'!$S18-'11-2025'!$V18+'11-2025'!$R18 -> 3560 | X18: =IFERROR(W18/30,"") -> 118.66667 | Y18: 0 | Z18: =IFERROR(+'11-2025'!$X18*'11-2025'!$Y18,"") -> 0 | AA18: 0 | AB18: =IFERROR(+'11-2025'!$X18*'11-2025'!$AA18,"") -> 0 | AC18: 0 | AD18: =IFERROR(+'11-2025'!$X18*'11-2025'!$AC18,"") -> 0 | AE18: 0 | AF18: =IFERROR(+'11-2025'!$X18*'11-2025'!$AE18,"") -> 0 | AG18: 0 | AH18: =IFERROR(+'11-2025'!$X18*'11-2025'!$AG18,"") -> 0 | AI18: 0 | AJ18: =IFERROR('11-2025'!$Z18+'11-2025'!$AB18+'11-2025'!$AD18+'11-2025'!$AF18+'11-2025'!$AH18+'11-2025'!$AI18,"") -> 0 | AK18: =IFERROR('11-2025'!$W18-'11-2025'!$AJ18,"") -> 3560 | AO18: 140 | AR18: 0 | AS18: 0 | AT18: 0 | AU18: 0 | AV18: 0 | AW18: 0 | AX18: 0 | AY18: 0 | AZ18: 0 | BA18: 0 | BB18: 0 | BC18: 0 | BD18: 0 | BE18: 4926.84 | BF18: 0 | BG18: 0 | BH18: 0 | BI18: 0 | BJ18: =BD18+BC18+BB18+BA18+AZ18+AY18+AX18+AW18+AV18+AU18+AT18+AS18+AR18+BE18+BF18+BG18+BH18+BI18 -> 4926.84 | BK18: =BJ18+AM18+AL18+'11-2025'!$N18+AN18+AO18 -> 9066.84 | BL18: ='11-2025'!$O18 -> 4000 | BM18: =BL18*18.75% -> 750 | BN18: =BL18*11% -> 440 | BO18: =+R18 -> 1666.6667 | BP18: =IF(BK18-BN18-BO18<0,0,BK18-BN18-BO18) -> 6960.1733 | BQ18: =IFERROR(BP18/'11-2025'!$J18,0)*12 -> 83522.08 | BR18: =IF(BQ18<=40000,0, IF(BQ18<=55000,(BQ18-40000)*10%, IF(BQ18<=70000,(BQ18-55000)*15%+1500, IF(BQ18<=200000,(BQ18-70000)*20%+1500+2250, IF(BQ18<=400000,(BQ18-200000)*22.5%+1500+2250+26000, IF(BQ18<=600000,(BQ18-400000)*25%+1500+2250+26000+45000, IF(AND(BQ18>600000,BQ18<=1200000),(BQ18-400000)*25%+1500+2250+26000+45000 +IFERROR(LOOKUP(BQ18,{600001;700001;800001;900001},{4000;6750;10250;15250}),0),IF(BQ18>1200000,((BQ18-1200000)*27.5%)+300000,0) ))))))) -> 6454.416 | BS18: =(BR18/12*'11-2025'!$J18) -> 537.868 | BT18: =BS18-'11-2025'!$V18 -> 537.868 | BU18: =IFERROR(+'11-2025'!$W18+AL18+AM18+BJ18-'11-2025'!$AJ18-BT18+AN18+AO18,"")-AL18+AP18+AQ18 -> 8088.972 | BX18: =+BU18-BW18 -> 8088.972 | BY18: فيزا
A19: 136 | B19: بهاء محمد السيد صالح أبو حسين | C19: المنصورة | D19: التحصيل | E19: متعدد | F19: مسئول موارد بشرية | G19: 45598 | I19: 28403211200572 | J19: 1 | K19: 5322.38 | N19: =SUM('11-2025'!$K19:$M19) -> 5322.38 | O19: 5230.7692 | P19: =O19*18.75% -> 980.76923 | Q19: =O19*11% -> 575.38462 | R19: 1666.6667 | S19: =IF(N19-Q19-R19<0,0,N19-Q19-R19) -> 3080.3287 | T19: =IFERROR(S19/J19,0)*12 -> 36963.945 | U19: =IF(T19<=40000,0, IF(T19<=55000,(T19-40000)*10%, IF(T19<=70000,(T19-55000)*15%+1500, IF(T19<=200000,(T19-70000)*20%+1500+2250, IF(T19<=400000,(T19-200000)*22.5%+1500+2250+26000, IF(T19<=600000,(T19-400000)*25%+1500+2250+26000+45000, IF(AND(T19>600000,T19<=1200000),(T19-400000)*25%+1500+2250+26000+45000 +IFERROR(LOOKUP(T19,{600001;700001;800001;900001},{4000;6750;10250;15250}),0),IF(T19>1200000,((T19-1200000)*27.5%)+300000,0) ))))))) -> 0 | V19: =U19/12*J19 -> 0 | W19: =+'11-2025'!$S19-'11-2025'!$V19+'11-2025'!$R19 -> 4746.9954 | X19: =IFERROR(W19/30,"") -> 158.23318 | Y19: 0 | Z19: =IFERROR(+'11-2025'!$X19*'11-2025'!$Y19,"") -> 0 | AA19: 0 | AB19: =IFERROR(+'11-2025'!$X19*'11-2025'!$AA19,"") -> 0 | AC19: 0 | AD19: =IFERROR(+'11-2025'!$X19*'11-2025'!$AC19,"") -> 0 | AE19: 0 | AF19: =IFERROR(+'11-2025'!$X19*'11-2025'!$AE19,"") -> 0 | AG19: 0 | AH19: =IFERROR(+'11-2025'!$X19*'11-2025'!$AG19,"") -> 0 | AI19: 0 | AJ19: =IFERROR('11-2025'!$Z19+'11-2025'!$AB19+'11-2025'!$AD19+'11-2025'!$AF19+'11-2025'!$AH19+'11-2025'!$AI19,"") -> 0 | AK19: =IFERROR('11-2025'!$W19-'11-2025'!$AJ19,"") -> 4746.9954 | AO19: 0 | AR19: 0 | AS19: 0 | AT19: 0 | AU19: 0 | AV19: 148.04198 | AW19: 0 | AX19: 0 | AY19: 0 | AZ19: 0 | BA19: 0 | BB19: 0 | BC19: 0 | BD19: 0 | BE19: 0 | BF19: 0 | BG19: 285 | BH19: 0 | BI19: 0 | BJ19: =BD19+BC19+BB19+BA19+AZ19+AY19+AX19+AW19+AV19+AU19+AT19+AS19+AR19+BE19+BF19+BG19+BH19+BI19 -> 433.04197 | BK19: =BJ19+AM19+AL19+'11-2025'!$N19+AN19+AO19 -> 5755.422 | BL19: ='11-2025'!$O19 -> 5230.7692 | BM19: =BL19*18.75% -> 980.76923 | BN19: =BL19*11% -> 575.38462 | BO19: =+R19 -> 1666.6667 | BP19: =IF(BK19-BN19-BO19<0,0,BK19-BN19-BO19) -> 3513.3707 | BQ19: =IFERROR(BP19/'11-2025'!$J19,0)*12 -> 42160.448 | BR19: =IF(BQ19<=40000,0, IF(BQ19<=55000,(BQ19-40000)*10%, IF(BQ19<=70000,(BQ19-55000)*15%+1500, IF(BQ19<=200000,(BQ19-70000)*20%+1500+2250, IF(BQ19<=400000,(BQ19-200000)*22.5%+1500+2250+26000, IF(BQ19<=600000,(BQ19-400000)*25%+1500+2250+26000+45000, IF(AND(BQ19>600000,BQ19<=1200000),(BQ19-400000)*25%+1500+2250+26000+45000 +IFERROR(LOOKUP(BQ19,{600001;700001;800001;900001},{4000;6750;10250;15250}),0),IF(BQ19>1200000,((BQ19-1200000)*27.5%)+300000,0) ))))))) -> 216.04483 | BS19: =(BR19/12*'11-2025'!$J19) -> 18.003736 | BT19: =BS19-'11-2025'!$V19 -> 18.003736 | BU19: =IFERROR(+'11-2025'!$W19+AL19+AM19+BJ19-'11-2025'!$AJ19-BT19+AN19+AO19,"")-AL19+AP19+AQ19 -> 5162.0336 | BX19: =+BU19-BW19 -> 5162.0336 | BY19: فيزا
A20: 150 | B20: هدى حسن السيد على الضوى | C20: 20أ القاهرة | D20: الادارى | E20: منسقى البيانات | F20: مشرف منسقى بيانات | G20: 45167 | I20: 30006102101386 | J20: 1 | K20: 5410.39 | N20: =SUM('11-2025'!$K20:$M20) -> 5410.39 | O20: 3730.8462 | P20: =O20*18.75% -> 699.53365 | Q20: =O20*11% -> 410.39308 | R20: 1666.6667 | S20: =IF(N20-Q20-R20<0,0,N20-Q20-R20) -> 3333.3303 | T20: =IFERROR(S20/J20,0)*12 -> 39999.963 | U20: =IF(T20<=40000,0, IF(T20<=55000,(T20-40000)*10%, IF(T20<=70000,(T20-55000)*15%+1500, IF(T20<=200000,(T20-70000)*20%+1500+2250, IF(T20<=400000,(T20-200000)*22.5%+1500+2250+26000, IF(T20<=600000,(T20-400000)*25%+1500+2250+26000+45000, IF(AND(T20>600000,T20<=1200000),(T20-400000)*25%+1500+2250+26000+45000 +IFERROR(LOOKUP(T20,{600001;700001;800001;900001},{4000;6750;10250;15250}),0),IF(T20>1200000,((T20-1200000)*27.5%)+300000,0) ))))))) -> 0 | V20: =U20/12*J20 -> 0 | W20: =+'11-2025'!$S20-'11-2025'!$V20+'11-2025'!$R20 -> 4999.9969 | X20: =IFERROR(W20/30,"") -> 166.66656 | Y20: 0 | Z20: =IFERROR(+'11-2025'!$X20*'11-2025'!$Y20,"") -> 0 | AA20: 0 | AB20: =IFERROR(+'11-2025'!$X20*'11-2025'!$AA20,"") -> 0 | AC20: 0 | AD20: =IFERROR(+'11-2025'!$X20*'11-2025'!$AC20,"") -> 0 | AE20: 0 | AF20: =IFERROR(+'11-2025'!$X20*'11-2025'!$AE20,"") -> 0 | AG20: 0 | AH20: =IFERROR(+'11-2025'!$X20*'11-2025'!$AG20,"") -> 0 | AI20: 0 | AJ20: =IFERROR('11-2025'!$Z20+'11-2025'!$AB20+'11-2025'!$AD20+'11-2025'!$AF20+'11-2025'!$AH20+'11-2025'!$AI20,"") -> 0 | AK20: =IFERROR('11-2025'!$W20-'11-2025'!$AJ20,"") -> 4999.9969 | AO20: 20 | AR20: 0 | AS20: 0 | AT20: 0 | AU20: 0 | AV20: 0 | AW20: 0 | AX20: 0 | AY20: 0 | AZ20: 0 | BA20: 0 | BB20: 0 | BC20: 0 | BD20: 0 | BE20: 0 | BF20: 0 | BG20: 0 | BH20: 0 | BI20: 0 | BJ20: =BD20+BC20+BB20+BA20+AZ20+AY20+AX20+AW20+AV20+AU20+AT20+AS20+AR20+BE20+BF20+BG20+BH20+BI20 -> 0 | BK20: =BJ20+AM20+AL20+'11-2025'!$N20+AN20+AO20 -> 5430.39 | BL20: ='11-2025'!$O20 -> 3730.8462 | BM20: =BL20*18.75% -> 699.53365 | BN20: =BL20*11% -> 410.39308 | BO20: =+R20 -> 1666.6667 | BP20: =IF(BK20-BN20-BO20<0,0,BK20-BN20-BO20) -> 3353.3303 | BQ20: =IFERROR(BP20/'11-2025'!$J20,0)*12 -> 40239.963 | BR20: =IF(BQ20<=40000,0, IF(BQ20<=55000,(BQ20-40000)*10%, IF(BQ20<=70000,(BQ20-55000)*15%+1500, IF(BQ20<=200000,(BQ20-70000)*20%+1500+2250, IF(BQ20<=400000,(BQ20-200000)*22.5%+1500+2250+26000, IF(BQ20<=600000,(BQ20-400000)*25%+1500+2250+26000+45000, IF(AND(BQ20>600000,BQ20<=1200000),(BQ20-400000)*25%+1500+2250+26000+45000 +IFERROR(LOOKUP(BQ20,{600001;700001;800001;900001},{4000;6750;10250;15250}),0),IF(BQ20>1200000,((BQ20-1200000)*27.5%)+300000,0) ))))))) -> 23.996308 | BS20: =(BR20/12*'11-2025'!$J20) -> 1.9996923 | BT20: 0 | BU20: =IFERROR(+'11-2025'!$W20+AL20+AM20+BJ20-'11-2025'!$AJ20-BT20+AN20+AO20,"")-AL20+AP20+AQ20 -> 5019.9969 | BX20: =+BU20-BW20 -> 5019.9969 | BY20: فيزا
A21: 151 | B21: احمد عبد الباسط عبد السلام محمد | C21: 20أ القاهرة | D21: الادارى | E21: المالية | F21: مدير حسابات | G21: 45171 | I21: 29805101502713 | J21: 1 | K21: 11274.76 | N21: =SUM('11-2025'!$K21:$M21) -> 11274.76 | O21: 5230.7692 | P21: =O21*18.75% -> 980.76923 | Q21: =O21*11% -> 575.38462 | R21: 1666.6667 | S21: =IF(N21-Q21-R21<0,0,N21-Q21-R21) -> 9032.7087 | T21: =IFERROR(S21/J21,0)*12 -> 108392.5 | U21: =IF(T21<=40000,0, IF(T21<=55000,(T21-40000)*10%, IF(T21<=70000,(T21-55000)*15%+1500, IF(T21<=200000,(T21-70000)*20%+1500+2250, IF(T21<=400000,(T21-200000)*22.5%+1500+2250+26000, IF(T21<=600000,(T21-400000)*25%+1500+2250+26000+45000, IF(AND(T21>600000,T21<=1200000),(T21-400000)*25%+1500+2250+26000+45000 +IFERROR(LOOKUP(T21,{600001;700001;800001;900001},{4000;6750;10250;15250}),0),IF(T21>1200000,((T21-1200000)*27.5%)+300000,0) ))))))) -> 11428.501 | V21: =U21/12*J21 -> 952.37508 | W21: =+'11-2025'!$S21-'11-2025'!$V21+'11-2025'!$R21 -> 9747.0003 | X21: =IFERROR(W21/30,"") -> 324.90001 | Z21: =IFERROR(+'11-2025'!$X21*'11-2025'!$Y21,"") -> 0 | AB21: =IFERROR(+'11-2025'!$X21*'11-2025'!$AA21,"") -> 0 | AC21: 30 | AD21: =IFERROR(+'11-2025'!$X21*'11-2025'!$AC21,"") -> 9747.0003 | AF21: =IFERROR(+'11-2025'!$X21*'11-2025'!$AE21,"") -> 0 | AH21: =IFERROR(+'11-2025'!$X21*'11-2025'!$AG21,"") -> 0 | AI21: 0 | AJ21: =IFERROR('11-2025'!$Z21+'11-2025'!$AB21+'11-2025'!$AD21+'11-2025'!$AF21+'11-2025'!$AH21+'11-2025'!$AI21,"") -> 9747.0003 | AK21: =IFERROR('11-2025'!$W21-'11-2025'!$AJ21,"") -> 0 | AR21: 0 | AS21: 0 | AT21: 0 | AU21: 0 | AV21: 0 | AW21: 0 | AX21: 0 | AY21: 0 | AZ21: 0 | BA21: 0 | BB21: 0 | BC21: 0 | BD21: 0 | BE21: 0 | BF21: 0 | BG21: 0 | BH21: 0 | BI21: 0 | BJ21: =BD21+BC21+BB21+BA21+AZ21+AY21+AX21+AW21+AV21+AU21+AT21+AS21+AR21+BE21+BF21+BG21+BH21+BI21 -> 0 | BK21: =BJ21+AM21+AL21+'11-2025'!$N21+AN21+AO21 -> 11274.76 | BL21: ='11-2025'!$O21 -> 5230.7692 | BM21: =BL21*18.75% -> 980.76923 | BN21: =BL21*11% -> 575.38462 | BO21: =+R21 -> 1666.6667 | BP21: =IF(BK21-BN21-BO21<0,0,BK21-BN21-BO21) -> 9032.7087 | BQ21: =IFERROR(BP21/'11-2025'!$J21,0)*12 -> 108392.5 | BR21: =IF(BQ21<=40000,0, IF(BQ21<=55000,(BQ21-40000)*10%, IF(BQ21<=70000,(BQ21-55000)*15%+1500, IF(BQ21<=200000,(BQ21-70000)*20%+1500+2250, IF(BQ21<=400000,(BQ21-200000)*22.5%+1500+2250+26000, IF(BQ21<=600000,(BQ21-400000)*25%+1500+2250+26000+45000, IF(AND(BQ21>600000,BQ21<=1200000),(BQ21-400000)*25%+1500+2250+26000+45000 +IFERROR(LOOKUP(BQ21,{600001;700001;800001;900001},{4000;6750;10250;15250}),0),IF(BQ21>1200000,((BQ21-1200000)*27.5%)+300000,0) ))))))) -> 11428.501 | BS21: =(BR21/12*'11-2025'!$J21) -> 952.37508 | BT21: 0 | BU21: =IFERROR(+'11-2025'!$W21+AL21+AM21+BJ21-'11-2025'!$AJ21-BT21+AN21+AO21,"")-AL21+AP21+AQ21 -> 0 | BX21: =+BU21-BW21 -> 0 | BY21: فيزا
A22: 162 | B22: عمرو على سليم محمد السيد | C22: المنصورة | D22: التحصيل | E22: متعدد | F22: مشرف تحصيل | G22: 45173 | I22: 28711011208851 | J22: 1 | K22: 6037.78 | N22: =SUM('11-2025'!$K22:$M22) -> 6037.78 | O22: 6000 | P22: =O22*18.75% -> 1125 | Q22: =O22*11% -> 660 | R22: 1666.6667 | S22: =IF(N22-Q22-R22<0,0,N22-Q22-R22) -> 3711.1133 | T22: =IFERROR(S22/J22,0)*12 -> 44533.36 | U22: =IF(T22<=40000,0, IF(T22<=55000,(T22-40000)*10%, IF(T22<=70000,(T22-55000)*15%+1500, IF(T22<=200000,(T22-70000)*20%+1500+2250, IF(T22<=400000,(T22-200000)*22.5%+1500+2250+26000, IF(T22<=600000,(T22-400000)*25%+1500+2250+26000+45000, IF(AND(T22>600000,T22<=1200000),(T22-400000)*25%+1500+2250+26000+45000 +IFERROR(LOOKUP(T22,{600001;700001;800001;900001},{4000;6750;10250;15250}),0),IF(T22>1200000,((T22-1200000)*27.5%)+300000,0) ))))))) -> 453.336 | V22: =U22/12*J22 -> 37.778 | W22: =+'11-2025'!$S22-'11-2025'!$V22+'11-2025'!$R22 -> 5340.002 | X22: =IFERROR(W22/30,"") -> 178.00007 | Y22: 0 | Z22: =IFERROR(+'11-2025'!$X22*'11-2025'!$Y22,"") -> 0 | AA22: 0 | AB22: =IFERROR(+'11-2025'!$X22*'11-2025'!$AA22,"") -> 0 | AC22: 0 | AD22: =IFERROR(+'11-2025'!$X22*'11-2025'!$AC22,"") -> 0 | AE22: 0 | AF22: =IFERROR(+'11-2025'!$X22*'11-2025'!$AE22,"") -> 0 | AG22: 0 | AH22: =IFERROR(+'11-2025'!$X22*'11-2025'!$AG22,"") -> 0 | AI22: 0 | AJ22: =IFERROR('11-2025'!$Z22+'11-2025'!$AB22+'11-2025'!$AD22+'11-2025'!$AF22+'11-2025'!$AH22+'11-2025'!$AI22,"") -> 0 | AK22: =IFERROR('11-2025'!$W22-'11-2025'!$AJ22,"") -> 5340.002 | AM22: 1000 | AO22: 0 | AR22: 0 | AS22: 350 | AT22: 0 | AU22: 2135.9137 | AV22: 49.347325 | AW22: 0 | AX22: 0 | AY22: 0 | AZ22: 0 | BA22: 0 | BB22: 0 | BC22: 0 | BD22: 0 | BE22: 0 | BF22: 0 | BG22: 0 | BH22: 0 | BI22: 0 | BJ22: =BD22+BC22+BB22+BA22+AZ22+AY22+AX22+AW22+AV22+AU22+AT22+AS22+AR22+BE22+BF22+BG22+BH22+BI22 -> 2535.261 | BK22: =BJ22+AM22+AL22+'11-2025'!$N22+AN22+AO22 -> 9573.041 | BL22: ='11-2025'!$O22 -> 6000 | BM22: =BL22*18.75% -> 1125 | BN22: =BL22*11% -> 660 | BO22: =+R22 -> 1666.6667 | BP22: =IF(BK22-BN22-BO22<0,0,BK22-BN22-BO22) -> 7246.3743 | BQ22: =IFERROR(BP22/'11-2025'!$J22,0)*12 -> 86956.492 | BR22: =IF(BQ22<=40000,0, IF(BQ22<=55000,(BQ22-40000)*10%, IF(BQ22<=70000,(BQ22-55000)*15%+1500, IF(BQ22<=200000,(BQ22-70000)*20%+1500+2250, IF(BQ22<=400000,(BQ22-200000)*22.5%+1500+2250+26000, IF(BQ22<=600000,(BQ22-400000)*25%+1500+2250+26000+45000, IF(AND(BQ22>600000,BQ22<=1200000),(BQ22-400000)*25%+1500+2250+26000+45000 +IFERROR(LOOKUP(BQ22,{600001;700001;800001;900001},{4000;6750;10250;15250}),0),IF(BQ22>1200000,((BQ22-1200000)*27.5%)+300000,0) ))))))) -> 7141.2984 | BS22: =(BR22/12*'11-2025'!$J22) -> 595.1082 | BT22: =BS22-'11-2025'!$V22 -> 557.3302 | BU22: =IFERROR(+'11-2025'!$W22+AL22+AM22+BJ22-'11-2025'!$AJ22-BT22+AN22+AO22,"")-AL22+AP22+AQ22 -> 8317.9328 | BV22: مكافاة اشراف | BX22: =+BU22-BW22 -> 8317.9328 | BY22: فيزا
